Workbook

Sheet DATA
A1: SO HD | B1: NGAY | C1: MA KH | D1: TEN KH | E1: MÃ NV | G1: MÃ HH | H1: TÊN SP | I1: SL | J1: ĐƠN GIÁ | K1: THÀNH TIỀN | L1: VAT | M1: NHÃN HÀNG | N1: CỬA HÀNG | O1: HỆ THỐNG
L2: =K2*1.1 -> 0 | M2: =IF(ISNUMBER(SEARCH("Azarine",H2)),"AZARINE",IF(ISNUMBER(SEARCH("Baking Soda",H2)),"BAKING SODA",IF(ISNUMBER(SEARCH("Fujitsu",H2)),"FUJITSU",IF(ISNUMBER(SEARCH("Coleman",H2)),"COLEMAN",""))))
L3: =K3*1.1 -> 0 | M3: =IF(ISNUMBER(SEARCH("Azarine",H3)),"AZARINE",IF(ISNUMBER(SEARCH("Baking Soda",H3)),"BAKING SODA",IF(ISNUMBER(SEARCH("Fujitsu",H3)),"FUJITSU",IF(ISNUMBER(SEARCH("Coleman",H3)),"COLEMAN",""))))
L4: =K4*1.1 -> 0 | M4: =IF(ISNUMBER(SEARCH("Azarine",H4)),"AZARINE",IF(ISNUMBER(SEARCH("Baking Soda",H4)),"BAKING SODA",IF(ISNUMBER(SEARCH("Fujitsu",H4)),"FUJITSU",IF(ISNUMBER(SEARCH("Coleman",H4)),"COLEMAN",""))))
L5: =K5*1.1 -> 0 | M5: =IF(ISNUMBER(SEARCH("Azarine",H5)),"AZARINE",IF(ISNUMBER(SEARCH("Baking Soda",H5)),"BAKING SODA",IF(ISNUMBER(SEARCH("Fujitsu",H5)),"FUJITSU",IF(ISNUMBER(SEARCH("Coleman",H5)),"COLEMAN",""))))
L6: =K6*1.1 -> 0 | M6: =IF(ISNUMBER(SEARCH("Azarine",H6)),"AZARINE",IF(ISNUMBER(SEARCH("Baking Soda",H6)),"BAKING SODA",IF(ISNUMBER(SEARCH("Fujitsu",H6)),"FUJITSU",IF(ISNUMBER(SEARCH("Coleman",H6)),"COLEMAN",""))))
L7: =K7*1.1 -> 0 | M7: =IF(ISNUMBER(SEARCH("Azarine",H7)),"AZARINE",IF(ISNUMBER(SEARCH("Baking Soda",H7)),"BAKING SODA",IF(ISNUMBER(SEARCH("Fujitsu",H7)),"FUJITSU",IF(ISNUMBER(SEARCH("Coleman",H7)),"COLEMAN",""))))
L8: =K8*1.1 -> 0 | M8: =IF(ISNUMBER(SEARCH("Azarine",H8)),"AZARINE",IF(ISNUMBER(SEARCH("Baking Soda",H8)),"BAKING SODA",IF(ISNUMBER(SEARCH("Fujitsu",H8)),"FUJITSU",IF(ISNUMBER(SEARCH("Coleman",H8)),"COLEMAN",""))))
L9: =K9*1.1 -> 0 | M9: =IF(ISNUMBER(SEARCH("Azarine",H9)),"AZARINE",IF(ISNUMBER(SEARCH("Baking Soda",H9)),"BAKING SODA",IF(ISNUMBER(SEARCH("Fujitsu",H9)),"FUJITSU",IF(ISNUMBER(SEARCH("Coleman",H9)),"COLEMAN",""))))
L10: =K10*1.1 -> 0 | M10: =IF(ISNUMBER(SEARCH("Azarine",H10)),"AZARINE",IF(ISNUMBER(SEARCH("Baking Soda",H10)),"BAKING SODA",IF(ISNUMBER(SEARCH("Fujitsu",H10)),"FUJITSU",IF(ISNUMBER(SEARCH("Coleman",H10)),"COLEMAN",""))))
L11: =K11*1.1 -> 0 | M11: =IF(ISNUMBER(SEARCH("Azarine",H11)),"AZARINE",IF(ISNUMBER(SEARCH("Baking Soda",H11)),"BAKING SODA",IF(ISNUMBER(SEARCH("Fujitsu",H11)),"FUJITSU",IF(ISNUMBER(SEARCH("Coleman",H11)),"COLEMAN",""))))
L12: =K12*1.1 -> 0 | M12: =IF(ISNUMBER(SEARCH("Azarine",H12)),"AZARINE",IF(ISNUMBER(SEARCH("Baking Soda",H12)),"BAKING SODA",IF(ISNUMBER(SEARCH("Fujitsu",H12)),"FUJITSU",IF(ISNUMBER(SEARCH("Coleman",H12)),"COLEMAN",""))))
L13: =K13*1.1 -> 0 | M13: =IF(ISNUMBER(SEARCH("Azarine",H13)),"AZARINE",IF(ISNUMBER(SEARCH("Baking Soda",H13)),"BAKING SODA",IF(ISNUMBER(SEARCH("Fujitsu",H13)),"FUJITSU",IF(ISNUMBER(SEARCH("Coleman",H13)),"COLEMAN",""))))
... L1217: =K1217*1.1 -> 0 | M1217: =IF(ISNUMBER(SEARCH("Azarine",H1217)),"AZARINE",IF(ISNUMBER(SEARCH("Baking Soda",H1217)),"BAKING SODA",IF(ISNUMBER(SEARCH("Fujitsu",H1217)),"FUJITSU",IF(ISNUMBER(SEARCH("Coleman",H1217)),"COLEMAN",""))))

Sheet SALES BY SYSTEM
F1: COLEMAN | H1: FUJITSU | J1: AZARINE | L1: BAKING SODA | O1: COLEMAN
A2: HỆ THỐNG | B2: SIÊU THỊ | C2: TỔNG TARGET | D2: THỰC ĐẠT | E2: % | O2: FUJITSU
F3: TARGET | G3: THỰC ĐẠT | H3: TARGET | I3: THỰC ĐẠT | J3: TARGET | K3: THỰC ĐẠT | L3: TARGET | M3: THỰC ĐẠT | O3: AZARINE
A4: LE NAM PHUONG | C4: =ROUNDUP(SUM(C5:C15),-5) -> 2079900000 | D4: =SUM(G4,I4,M4,K4) -> 0 | E4: =D4/C4 -> 0 | F4: =IFERROR(SUM(F5:F15),"") -> 3.5116518e+08 | G4: =IFERROR(SUM(G5:G15),"") -> 0 | H4: =IFERROR(SUM(H5:H15),"") -> 1.6488051e+08 | I4: =IFERROR(SUM(I5:I15),"") -> 0 | J4: =IFERROR(SUM(J5:J15),"") -> 2.008894e+08 | K4: =IFERROR(SUM(K5:K15),"") -> 0 | L4: =IFERROR(SUM(L5:L15),"") -> 1.3629537e+09 | M4: =IFERROR(SUM(M5:M15),"") -> 0 | O4: BAKING SODA
A5: ACE | B5: 3 | C5: =SUMIFS('SALE BY STORE'!$H$3:$H$982,'SALE BY STORE'!$B$3:$B$982,'SALES BY SYSTEM'!$A5) -> 46261523 | D5: =VALUE(SUM(G5,I5,M5,K5)) -> 0 | E5: =IFERROR(D5/C5,"") -> 0 | F5: =SUMIFS('SALE BY STORE'!$K$3:$K$982,'SALE BY STORE'!$B$3:$B$982,'SALES BY SYSTEM'!$A5) -> 33206507 | G5: =SUMIFS(DATA!$L:$L,DATA!$O:$O,'SALES BY SYSTEM'!$A5,DATA!$M:$M,'SALES BY SYSTEM'!$O$1) -> 0 | H5: =SUMIFS('SALE BY STORE'!$N$3:$N$982,'SALE BY STORE'!$B$3:$B$982,'SALES BY SYSTEM'!$A5) -> 13055016 | I5: =SUMIFS(DATA!$L:$L,DATA!$O:$O,'SALES BY SYSTEM'!$A5,DATA!$M:$M,'SALES BY SYSTEM'!$O$2) -> 0 | J5: =SUMIFS('SALE BY STORE'!$T$3:$T$982,'SALE BY STORE'!$B$3:$B$982,'SALES BY SYSTEM'!$A5) -> 0 | K5: =SUMIFS(DATA!$L:$L,DATA!$O:$O,'SALES BY SYSTEM'!$A5,DATA!$M:$M,'SALES BY SYSTEM'!$O$3) -> 0 | L5: =SUMIFS('SALE BY STORE'!$Q$3:$Q$982,'SALE BY STORE'!$B$3:$B$982,'SALES BY SYSTEM'!$A5) -> 0 | M5: =SUMIFS(DATA!$L:$L,DATA!$O:$O,'SALES BY SYSTEM'!$A5,DATA!$M:$M,'SALES BY SYSTEM'!$O$4) -> 0
A6: AEON | B6: 7 | C6: =SUMIFS('SALE BY STORE'!$H$3:$H$982,'SALE BY STORE'!$B$3:$B$982,'SALES BY SYSTEM'!$A6) -> 0 | D6: =VALUE(SUM(G6,I6,M6,K6)) -> 0 | E6: =IFERROR(D6/C6,"") | F6: =SUMIFS('SALE BY STORE'!$K$3:$K$982,'SALE BY STORE'!$B$3:$B$982,'SALES BY SYSTEM'!$A6) -> 0 | G6: =SUMIFS(DATA!$L:$L,DATA!$O:$O,'SALES BY SYSTEM'!$A6,DATA!$M:$M,'SALES BY SYSTEM'!$O$1) -> 0 | H6: =SUMIFS('SALE BY STORE'!$N$3:$N$982,'SALE BY STORE'!$B$3:$B$982,'SALES BY SYSTEM'!$A6) -> 0 | I6: =SUMIFS(DATA!$L:$L,DATA!$O:$O,'SALES BY SYSTEM'!$A6,DATA!$M:$M,'SALES BY SYSTEM'!$O$2) -> 0 | J6: =SUMIFS('SALE BY STORE'!$T$3:$T$982,'SALE BY STORE'!$B$3:$B$982,'SALES BY SYSTEM'!$A6) -> 0 | K6: =SUMIFS(DATA!$L:$L,DATA!$O:$O,'SALES BY SYSTEM'!$A6,DATA!$M:$M,'SALES BY SYSTEM'!$O$3) -> 0 | L6: =SUMIFS('SALE BY STORE'!$Q$3:$Q$982,'SALE BY STORE'!$B$3:$B$982,'SALES BY SYSTEM'!$A6) -> 0 | M6: =SUMIFS(DATA!$L:$L,DATA!$O:$O,'SALES BY SYSTEM'!$A6,DATA!$M:$M,'SALES BY SYSTEM'!$O$4) -> 0 | O6: BAKING SODA
A7: BIG C | B7: 48 | C7: =SUMIFS('SALE BY STORE'!$H$3:$H$982,'SALE BY STORE'!$B$3:$B$982,'SALES BY SYSTEM'!$A7) -> 4.9712342e+08 | D7: =VALUE(SUM(G7,I7,M7,K7)) -> 0 | E7: =IFERROR(D7/C7,"") -> 0 | F7: =SUMIFS('SALE BY STORE'!$K$3:$K$982,'SALE BY STORE'!$B$3:$B$982,'SALES BY SYSTEM'!$A7) -> 0 | G7: =SUMIFS(DATA!$L:$L,DATA!$O:$O,'SALES BY SYSTEM'!$A7,DATA!$M:$M,'SALES BY SYSTEM'!$O$1) -> 0 | H7: =SUMIFS('SALE BY STORE'!$N$3:$N$982,'SALE BY STORE'!$B$3:$B$982,'SALES BY SYSTEM'!$A7) -> 85244906 | I7: =SUMIFS(DATA!$L:$L,DATA!$O:$O,'SALES BY SYSTEM'!$A7,DATA!$M:$M,'SALES BY SYSTEM'!$O$2) -> 0 | J7: =SUMIFS('SALE BY STORE'!$T$3:$T$982,'SALE BY STORE'!$B$3:$B$982,'SALES BY SYSTEM'!$A7) -> 0 | K7: =SUMIFS(DATA!$L:$L,DATA!$O:$O,'SALES BY SYSTEM'!$A7,DATA!$M:$M,'SALES BY SYSTEM'!$O$3) -> 0 | L7: =SUMIFS('SALE BY STORE'!$Q$3:$Q$982,'SALE BY STORE'!$B$3:$B$982,'SALES BY SYSTEM'!$A7) -> 4.1187851e+08 | M7: =SUMIFS(DATA!$L:$L,DATA!$O:$O,'SALES BY SYSTEM'!$A7,DATA!$M:$M,'SALES BY SYSTEM'!$O$4) -> 0 | O7: FUJITSU
A8: EMART | B8: 1 | C8: =SUMIFS('SALE BY STORE'!$H$3:$H$982,'SALE BY STORE'!$B$3:$B$982,'SALES BY SYSTEM'!$A8) -> 65275082 | D8: =VALUE(SUM(G8,I8,M8,K8)) -> 0 | E8: =IFERROR(D8/C8,"") -> 0 | F8: =SUMIFS('SALE BY STORE'!$K$3:$K$982,'SALE BY STORE'!$B$3:$B$982,'SALES BY SYSTEM'!$A8) -> 0 | G8: =SUMIFS(DATA!$L:$L,DATA!$O:$O,'SALES BY SYSTEM'!$A8,DATA!$M:$M,'SALES BY SYSTEM'!$O$1) -> 0 | H8: =SUMIFS('SALE BY STORE'!$N$3:$N$982,'SALE BY STORE'!$B$3:$B$982,'SALES BY SYSTEM'!$A8) -> 65275082 | I8: =SUMIFS(DATA!$L:$L,DATA!$O:$O,'SALES BY SYSTEM'!$A8,DATA!$M:$M,'SALES BY SYSTEM'!$O$2) -> 0 | J8: =SUMIFS('SALE BY STORE'!$T$3:$T$982,'SALE BY STORE'!$B$3:$B$982,'SALES BY SYSTEM'!$A8) -> 0 | K8: =SUMIFS(DATA!$L:$L,DATA!$O:$O,'SALES BY SYSTEM'!$A8,DATA!$M:$M,'SALES BY SYSTEM'!$O$3) -> 0 | L8: =SUMIFS('SALE BY STORE'!$Q$3:$Q$982,'SALE BY STORE'!$B$3:$B$982,'SALES BY SYSTEM'!$A8) -> 0 | M8: =SUMIFS(DATA!$L:$L,DATA!$O:$O,'SALES BY SYSTEM'!$A8,DATA!$M:$M,'SALES BY SYSTEM'!$O$4) -> 0 | O8: ADIDAS
A9: MEGA | B9: 19 | C9: =SUMIFS('SALE BY STORE'!$H$3:$H$982,'SALE BY STORE'!$B$3:$B$982,'SALES BY SYSTEM'!$A9) -> 4.9576643e+08 | D9: =VALUE(SUM(G9,I9,M9,K9)) -> 0 | E9: =IFERROR(D9/C9,"") -> 0 | F9: =SUMIFS('SALE BY STORE'!$K$3:$K$982,'SALE BY STORE'!$B$3:$B$982,'SALES BY SYSTEM'!$A9) -> 3.1795867e+08 | G9: =SUMIFS(DATA!$L:$L,DATA!$O:$O,'SALES BY SYSTEM'!$A9,DATA!$M:$M,'SALES BY SYSTEM'!$O$1) -> 0 | H9: =SUMIFS('SALE BY STORE'!$N$3:$N$982,'SALE BY STORE'!$B$3:$B$982,'SALES BY SYSTEM'!$A9) -> 0 | I9: =SUMIFS(DATA!$L:$L,DATA!$O:$O,'SALES BY SYSTEM'!$A9,DATA!$M:$M,'SALES BY SYSTEM'!$O$2) -> 0 | J9: =SUMIFS('SALE BY STORE'!$T$3:$T$982,'SALE BY STORE'!$B$3:$B$982,'SALES BY SYSTEM'!$A9) -> 0 | K9: =SUMIFS(DATA!$L:$L,DATA!$O:$O,'SALES BY SYSTEM'!$A9,DATA!$M:$M,'SALES BY SYSTEM'!$O$3) -> 0 | L9: =SUMIFS('SALE BY STORE'!$Q$3:$Q$982,'SALE BY STORE'!$B$3:$B$982,'SALES BY SYSTEM'!$A9) -> 1.7780775e+08 | M9: =SUMIFS(DATA!$L:$L,DATA!$O:$O,'SALES BY SYSTEM'!$A9,DATA!$M:$M,'SALES BY SYSTEM'!$O$4) -> 0 | O9: COLEMAN
A10: HOMEMART | B10: 4 | C10: =SUMIFS('SALE BY STORE'!$H$3:$H$982,'SALE BY STORE'!$B$3:$B$982,'SALES BY SYSTEM'!$A10) -> 0 | D10: =VALUE(SUM(G10,I10,M10,K10)) -> 0 | E10: =IFERROR(D10/C10,"") | F10: =SUMIFS('SALE BY STORE'!$K$3:$K$982,'SALE BY STORE'!$B$3:$B$982,'SALES BY SYSTEM'!$A10) -> 0 | G10: =SUMIFS(DATA!$L:$L,DATA!$O:$O,'SALES BY SYSTEM'!$A10,DATA!$M:$M,'SALES BY SYSTEM'!$O$1) -> 0 | H10: =SUMIFS('SALE BY STORE'!$N$3:$N$982,'SALE BY STORE'!$B$3:$B$982,'SALES BY SYSTEM'!$A10) -> 0 | I10: =SUMIFS(DATA!$L:$L,DATA!$O:$O,'SALES BY SYSTEM'!$A10,DATA!$M:$M,'SALES BY SYSTEM'!$O$2) -> 0 | J10: =SUMIFS('SALE BY STORE'!$T$3:$T$982,'SALE BY STORE'!$B$3:$B$982,'SALES BY SYSTEM'!$A10) -> 0 | K10: =SUMIFS(DATA!$L:$L,DATA!$O:$O,'SALES BY SYSTEM'!$A10,DATA!$M:$M,'SALES BY SYSTEM'!$O$3) -> 0 | L10: =SUMIFS('SALE BY STORE'!$Q$3:$Q$982,'SALE BY STORE'!$B$3:$B$982,'SALES BY SYSTEM'!$A10) -> 0 | M10: =SUMIFS(DATA!$L:$L,DATA!$O:$O,'SALES BY SYSTEM'!$A10,DATA!$M:$M,'SALES BY SYSTEM'!$O$4) -> 0
A11: SIEU THI AN PHU | B11: 1 | C11: =SUMIFS('SALE BY STORE'!$H$3:$H$982,'SALE BY STORE'!$B$3:$B$982,'SALES BY SYSTEM'!$A11) -> 6284570.2 | D11: =VALUE(SUM(G11,I11,M11,K11)) -> 0 | E11: =IFERROR(D11/C11,"") -> 0 | F11: =SUMIFS('SALE BY STORE'!$K$3:$K$982,'SALE BY STORE'!$B$3:$B$982,'SALES BY SYSTEM'!$A11) -> 0 | G11: =SUMIFS(DATA!$L:$L,DATA!$O:$O,'SALES BY SYSTEM'!$A11,DATA!$M:$M,'SALES BY SYSTEM'!$O$1) -> 0 | H11: =SUMIFS('SALE BY STORE'!$N$3:$N$982,'SALE BY STORE'!$B$3:$B$982,'SALES BY SYSTEM'!$A11) -> 1305501.6 | I11: =SUMIFS(DATA!$L:$L,DATA!$O:$O,'SALES BY SYSTEM'!$A11,DATA!$M:$M,'SALES BY SYSTEM'!$O$2) -> 0 | J11: =SUMIFS('SALE BY STORE'!$T$3:$T$982,'SALE BY STORE'!$B$3:$B$982,'SALES BY SYSTEM'!$A11) -> 0 | K11: =SUMIFS(DATA!$L:$L,DATA!$O:$O,'SALES BY SYSTEM'!$A11,DATA!$M:$M,'SALES BY SYSTEM'!$O$3) -> 0 | L11: =SUMIFS('SALE BY STORE'!$Q$3:$Q$982,'SALE BY STORE'!$B$3:$B$982,'SALES BY SYSTEM'!$A11) -> 4979068.6 | M11: =SUMIFS(DATA!$L:$L,DATA!$O:$O,'SALES BY SYSTEM'!$A11,DATA!$M:$M,'SALES BY SYSTEM'!$O$4) -> 0
A12: WELLNESS | B12: 7 | C12: =SUMIFS('SALE BY STORE'!$H$3:$H$982,'SALE BY STORE'!$B$3:$B$982,'SALES BY SYSTEM'!$A12) -> 0 | D12: =VALUE(SUM(G12,I12,M12,K12)) -> 0 | E12: =IFERROR(D12/C12,"") | F12: =SUMIFS('SALE BY STORE'!$K$3:$K$982,'SALE BY STORE'!$B$3:$B$982,'SALES BY SYSTEM'!$A12) -> 0 | G12: =SUMIFS(DATA!$L:$L,DATA!$O:$O,'SALES BY SYSTEM'!$A12,DATA!$M:$M,'SALES BY SYSTEM'!$O$1) -> 0 | H12: =SUMIFS('SALE BY STORE'!$N$3:$N$982,'SALE BY STORE'!$B$3:$B$982,'SALES BY SYSTEM'!$A12) -> 0 | I12: =SUMIFS(DATA!$L:$L,DATA!$O:$O,'SALES BY SYSTEM'!$A12,DATA!$M:$M,'SALES BY SYSTEM'!$O$2) -> 0 | J12: =SUMIFS('SALE BY STORE'!$T$3:$T$982,'SALE BY STORE'!$B$3:$B$982,'SALES BY SYSTEM'!$A12) -> 0 | K12: =SUMIFS(DATA!$L:$L,DATA!$O:$O,'SALES BY SYSTEM'!$A12,DATA!$M:$M,'SALES BY SYSTEM'!$O$3) -> 0 | L12: =SUMIFS('SALE BY STORE'!$Q$3:$Q$982,'SALE BY STORE'!$B$3:$B$982,'SALES BY SYSTEM'!$A12) -> 0 | M12: =SUMIFS(DATA!$L:$L,DATA!$O:$O,'SALES BY SYSTEM'!$A12,DATA!$M:$M,'SALES BY SYSTEM'!$O$4) -> 0
A13: AEON CITI | B13: 20 | C13: =SUMIFS('SALE BY STORE'!$H$3:$H$982,'SALE BY STORE'!$B$3:$B$982,'SALES BY SYSTEM'!$A13) -> 0 | D13: =VALUE(SUM(G13,I13,M13,K13)) -> 0 | E13: =IFERROR(D13/C13,"") | F13: =SUMIFS('SALE BY STORE'!$K$3:$K$982,'SALE BY STORE'!$B$3:$B$982,'SALES BY SYSTEM'!$A13) -> 0 | G13: =SUMIFS(DATA!$L:$L,DATA!$O:$O,'SALES BY SYSTEM'!$A13,DATA!$M:$M,'SALES BY SYSTEM'!$O$1) -> 0 | H13: =SUMIFS('SALE BY STORE'!$N$3:$N$982,'SALE BY STORE'!$B$3:$B$982,'SALES BY SYSTEM'!$A13) -> 0 | I13: =SUMIFS(DATA!$L:$L,DATA!$O:$O,'SALES BY SYSTEM'!$A13,DATA!$M:$M,'SALES BY SYSTEM'!$O$2) -> 0 | J13: =SUMIFS('SALE BY STORE'!$T$3:$T$982,'SALE BY STORE'!$B$3:$B$982,'SALES BY SYSTEM'!$A13) -> 0 | K13: =SUMIFS(DATA!$L:$L,DATA!$O:$O,'SALES BY SYSTEM'!$A13,DATA!$M:$M,'SALES BY SYSTEM'!$O$3) -> 0 | L13: =SUMIFS('SALE BY STORE'!$Q$3:$Q$982,'SALE BY STORE'!$B$3:$B$982,'SALES BY SYSTEM'!$A13) -> 0 | M13: =SUMIFS(DATA!$L:$L,DATA!$O:$O,'SALES BY SYSTEM'!$A13,DATA!$M:$M,'SALES BY SYSTEM'!$O$4) -> 0
A14: GUARDIAN | C14: =SUMIFS('SALE BY STORE'!$H$3:$H$982,'SALE BY STORE'!$B$3:$B$982,'SALES BY SYSTEM'!$A14) -> 2.008894e+08 | D14: =VALUE(SUM(G14,I14,M14,K14)) -> 0 | F14: =SUMIFS('SALE BY STORE'!$K$3:$K$982,'SALE BY STORE'!$B$3:$B$982,'SALES BY SYSTEM'!$A14) -> 0 | G14: =SUMIFS(DATA!$L:$L,DATA!$O:$O,'SALES BY SYSTEM'!$A14,DATA!$M:$M,'SALES BY SYSTEM'!$O$1) -> 0 | H14: =SUMIFS('SALE BY STORE'!$N$3:$N$982,'SALE BY STORE'!$B$3:$B$982,'SALES BY SYSTEM'!$A14) -> 0 | I14: =SUMIFS(DATA!$L:$L,DATA!$O:$O,'SALES BY SYSTEM'!$A14,DATA!$M:$M,'SALES BY SYSTEM'!$O$2) -> 0 | J14: =SUMIFS('SALE BY STORE'!$T$3:$T$982,'SALE BY STORE'!$B$3:$B$982,'SALES BY SYSTEM'!$A14) -> 2.008894e+08 | K14: =SUMIFS(DATA!$L:$L,DATA!$O:$O,'SALES BY SYSTEM'!$A14,DATA!$M:$M,'SALES BY SYSTEM'!$O$3) -> 0 | L14: =SUMIFS('SALE BY STORE'!$Q$3:$Q$982,'SALE BY STORE'!$B$3:$B$982,'SALES BY SYSTEM'!$A14) -> 0 | M14: =SUMIFS(DATA!$L:$L,DATA!$O:$O,'SALES BY SYSTEM'!$A14,DATA!$M:$M,'SALES BY SYSTEM'!$O$4) -> 0
A15: BHX | B15: 1698 | C15: =SUMIFS('SALE BY STORE'!$H$3:$H$982,'SALE BY STORE'!$B$3:$B$982,'SALES BY SYSTEM'!$A15) -> 7.6828838e+08 | D15: =VALUE(SUM(G15,I15,M15,K15)) -> 0 | E15: =IFERROR(D15/C15,"") -> 0 | F15: =SUMIFS('SALE BY STORE'!$K$3:$K$982,'SALE BY STORE'!$B$3:$B$982,'SALES BY SYSTEM'!$A15) -> 0 | G15: =SUMIFS(DATA!$L:$L,DATA!$O:$O,'SALES BY SYSTEM'!$A15,DATA!$M:$M,'SALES BY SYSTEM'!$O$1) -> 0 | H15: =SUMIFS('SALE BY STORE'!$N$3:$N$982,'SALE BY STORE'!$B$3:$B$982,'SALES BY SYSTEM'!$A15) -> 0 | I15: =SUMIFS(DATA!$L:$L,DATA!$O:$O,'SALES BY SYSTEM'!$A15,DATA!$M:$M,'SALES BY SYSTEM'!$O$2) -> 0 | J15: =SUMIFS('SALE BY STORE'!$T$3:$T$982,'SALE BY STORE'!$B$3:$B$982,'SALES BY SYSTEM'!$A15) -> 0 | K15: =SUMIFS(DATA!$L:$L,DATA!$O:$O,'SALES BY SYSTEM'!$A15,DATA!$M:$M,'SALES BY SYSTEM'!$O$3) -> 0 | L15: =SUMIFS('SALE BY STORE'!$Q$3:$Q$982,'SALE BY STORE'!$B$3:$B$982,'SALES BY SYSTEM'!$A15) -> 7.6828838e+08 | M15: =SUMIFS(DATA!$L:$L,DATA!$O:$O,'SALES BY SYSTEM'!$A15,DATA!$M:$M,'SALES BY SYSTEM'!$O$4) -> 0
A16: VAVANCY-VU MINH TUAN | C16: =ROUNDUP(SUM(C17:C20),-5) -> 788500000 | D16: =SUM(G16,I16,M16,K16) -> 0 | E16: =D16/C16 -> 0 | F16: =IFERROR(SUM(F17:F20),"") -> 0 | G16: =IFERROR(SUM(G17:G20),"") -> 0 | H16: =IFERROR(SUM(H17:H20),"") -> 2.5370249e+08 | I16: =IFERROR(SUM(I17:I20),"") -> 0 | J16: =IFERROR(SUM(J17:J20),"") -> 0 | K16: =IFERROR(SUM(K17:K20),"") -> 0 | L16: =IFERROR(SUM(L17:L20),"") -> 5.3475196e+08 | M16: =IFERROR(SUM(M17:M20),"") -> 0
A17: COOP CHEERS | C17: =SUMIFS('SALE BY STORE'!$H$3:$H$982,'SALE BY STORE'!$B$3:$B$982,'SALES BY SYSTEM'!$A17) -> 13055016 | D17: =VALUE(SUM(G17,I17,M17,K17)) -> 0 | E17: =IFERROR(D17/C17,"") -> 0 | F17: =SUMIFS('SALE BY STORE'!$K$3:$K$982,'SALE BY STORE'!$B$3:$B$982,'SALES BY SYSTEM'!$A17) -> 0 | G17: =SUMIFS(DATA!$L:$L,DATA!$O:$O,'SALES BY SYSTEM'!$A17,DATA!$M:$M,'SALES BY SYSTEM'!$O$1) -> 0 | H17: =SUMIFS('SALE BY STORE'!$N$3:$N$982,'SALE BY STORE'!$B$3:$B$982,'SALES BY SYSTEM'!$A17) -> 13055016 | I17: =SUMIFS(DATA!$L:$L,DATA!$O:$O,'SALES BY SYSTEM'!$A17,DATA!$M:$M,'SALES BY SYSTEM'!$O$2) -> 0 | J17: =SUMIFS('SALE BY STORE'!$T$3:$T$982,'SALE BY STORE'!$B$3:$B$982,'SALES BY SYSTEM'!$A17) -> 0 | K17: =SUMIFS(DATA!$L:$L,DATA!$O:$O,'SALES BY SYSTEM'!$A17,DATA!$M:$M,'SALES BY SYSTEM'!$O$3) -> 0 | L17: =SUMIFS('SALE BY STORE'!$Q$3:$Q$982,'SALE BY STORE'!$B$3:$B$982,'SALES BY SYSTEM'!$A17) -> 0 | M17: =SUMIFS(DATA!$L:$L,DATA!$O:$O,'SALES BY SYSTEM'!$A17,DATA!$M:$M,'SALES BY SYSTEM'!$O$4) -> 0
A18: COOP EXTRA | C18: =SUMIFS('SALE BY STORE'!$H$3:$H$982,'SALE BY STORE'!$B$3:$B$982,'SALES BY SYSTEM'!$A18) -> 74411008 | D18: =VALUE(SUM(G18,I18,M18,K18)) -> 0 | E18: =IFERROR(D18/C18,"") -> 0 | F18: =SUMIFS('SALE BY STORE'!$K$3:$K$982,'SALE BY STORE'!$B$3:$B$982,'SALES BY SYSTEM'!$A18) -> 0 | G18: =SUMIFS(DATA!$L:$L,DATA!$O:$O,'SALES BY SYSTEM'!$A18,DATA!$M:$M,'SALES BY SYSTEM'!$O$1) -> 0 | H18: =SUMIFS('SALE BY STORE'!$N$3:$N$982,'SALE BY STORE'!$B$3:$B$982,'SALES BY SYSTEM'!$A18) -> 22628695 | I18: =SUMIFS(DATA!$L:$L,DATA!$O:$O,'SALES BY SYSTEM'!$A18,DATA!$M:$M,'SALES BY SYSTEM'!$O$2) -> 0 | J18: =SUMIFS('SALE BY STORE'!$T$3:$T$982,'SALE BY STORE'!$B$3:$B$982,'SALES BY SYSTEM'!$A18) -> 0 | K18: =SUMIFS(DATA!$L:$L,DATA!$O:$O,'SALES BY SYSTEM'!$A18,DATA!$M:$M,'SALES BY SYSTEM'!$O$3) -> 0 | L18: =SUMIFS('SALE BY STORE'!$Q$3:$Q$982,'SALE BY STORE'!$B$3:$B$982,'SALES BY SYSTEM'!$A18) -> 51782313 | M18: =SUMIFS(DATA!$L:$L,DATA!$O:$O,'SALES BY SYSTEM'!$A18,DATA!$M:$M,'SALES BY SYSTEM'!$O$4) -> 0
A19: COOP MART | C19: =SUMIFS('SALE BY STORE'!$H$3:$H$982,'SALE BY STORE'!$B$3:$B$982,'SALES BY SYSTEM'!$A19) -> 6.3744657e+08 | D19: =VALUE(SUM(G19,I19,M19,K19)) -> 0 | E19: =IFERROR(D19/C19,"") -> 0 | F19: =SUMIFS('SALE BY STORE'!$K$3:$K$982,'SALE BY STORE'!$B$3:$B$982,'SALES BY SYSTEM'!$A19) -> 0 | G19: =SUMIFS(DATA!$L:$L,DATA!$O:$O,'SALES BY SYSTEM'!$A19,DATA!$M:$M,'SALES BY SYSTEM'!$O$1) -> 0 | H19: =SUMIFS('SALE BY STORE'!$N$3:$N$982,'SALE BY STORE'!$B$3:$B$982,'SALES BY SYSTEM'!$A19) -> 2.149726e+08 | I19: =SUMIFS(DATA!$L:$L,DATA!$O:$O,'SALES BY SYSTEM'!$A19,DATA!$M:$M,'SALES BY SYSTEM'!$O$2) -> 0 | J19: =SUMIFS('SALE BY STORE'!$T$3:$T$982,'SALE BY STORE'!$B$3:$B$982,'SALES BY SYSTEM'!$A19) -> 0 | K19: =SUMIFS(DATA!$L:$L,DATA!$O:$O,'SALES BY SYSTEM'!$A19,DATA!$M:$M,'SALES BY SYSTEM'!$O$3) -> 0 | L19: =SUMIFS('SALE BY STORE'!$Q$3:$Q$982,'SALE BY STORE'!$B$3:$B$982,'SALES BY SYSTEM'!$A19) -> 4.2247397e+08 | M19: =SUMIFS(DATA!$L:$L,DATA!$O:$O,'SALES BY SYSTEM'!$A19,DATA!$M:$M,'SALES BY SYSTEM'!$O$4) -> 0
A20: COOP FOOD | C20: =SUMIFS('SALE BY STORE'!$H$3:$H$982,'SALE BY STORE'!$B$3:$B$982,'SALES BY SYSTEM'!$A20) -> 63541854 | D20: =VALUE(SUM(G20,I20,M20,K20)) -> 0 | E20: =IFERROR(D20/C20,"") -> 0 | F20: =SUMIFS('SALE BY STORE'!$K$3:$K$982,'SALE BY STORE'!$B$3:$B$982,'SALES BY SYSTEM'!$A20) -> 0 | G20: =SUMIFS(DATA!$L:$L,DATA!$O:$O,'SALES BY SYSTEM'!$A20,DATA!$M:$M,'SALES BY SYSTEM'!$O$1) -> 0 | H20: =SUMIFS('SALE BY STORE'!$N$3:$N$982,'SALE BY STORE'!$B$3:$B$982,'SALES BY SYSTEM'!$A20) -> 3046170.5 | I20: =SUMIFS(DATA!$L:$L,DATA!$O:$O,'SALES BY SYSTEM'!$A20,DATA!$M:$M,'SALES BY SYSTEM'!$O$2) -> 0 | J20: =SUMIFS('SALE BY STORE'!$T$3:$T$982,'SALE BY STORE'!$B$3:$B$982,'SALES BY SYSTEM'!$A20) -> 0 | K20: =SUMIFS(DATA!$L:$L,DATA!$O:$O,'SALES BY SYSTEM'!$A20,DATA!$M:$M,'SALES BY SYSTEM'!$O$3) -> 0 | L20: =SUMIFS('SALE BY STORE'!$Q$3:$Q$982,'SALE BY STORE'!$B$3:$B$982,'SALES BY SYSTEM'!$A20) -> 60495683 | M20: =SUMIFS(DATA!$L:$L,DATA!$O:$O,'SALES BY SYSTEM'!$A20,DATA!$M:$M,'SALES BY SYSTEM'!$O$4) -> 0
A21: TRAN THI THAO NGUYEN | C21: =ROUNDUP(SUM(C22:C47),-5) -> 2131700000 | D21: =SUM(D22:D49) -> 0 | E21: =IFERROR(D21/C21,"") -> 0 | F21: =SUM(F22:F47) -> 0 | G21: =SUM(G22:G49) -> 0 | H21: =SUM(H22:H49) -> 5.5578631e+08 | I21: =SUM(I22:I49) -> 0 | J21: =SUM(J22:J49) -> 0 | K21: =SUM(K22:K49) -> 0 | L21: =SUM(L22:L49) -> 1.5758704e+09 | M21: =SUM(M22:M49) -> 0
A22: HOMEFRESH MART | C22: =SUMIFS('SALE BY STORE'!$H$3:$H$982,'SALE BY STORE'!$B$3:$B$982,'SALES BY SYSTEM'!$A22) -> 1305501.6 | D22: =VALUE(SUM(G22,K22,I22,M22)) -> 0 | E22: =IFERROR(D22/C22,"") -> 0 | F22: =SUMIFS('SALE BY STORE'!$K$3:$K$982,'SALE BY STORE'!$B$3:$B$982,'SALES BY SYSTEM'!$A22) -> 0 | G22: =SUMIFS(DATA!$L:$L,DATA!$O:$O,'SALES BY SYSTEM'!$A22,DATA!$M:$M,'SALES BY SYSTEM'!$O$1) -> 0 | H22: =SUMIFS('SALE BY STORE'!$N$3:$N$982,'SALE BY STORE'!$B$3:$B$982,'SALES BY SYSTEM'!$A22) -> 1305501.6 | I22: =SUMIFS(DATA!$L:$L,DATA!$O:$O,'SALES BY SYSTEM'!$A22,DATA!$M:$M,'SALES BY SYSTEM'!$O$2) -> 0 | J22: =SUMIFS('SALE BY STORE'!$T$3:$T$982,'SALE BY STORE'!$B$3:$B$982,'SALES BY SYSTEM'!$A22) -> 0 | K22: =SUMIFS(DATA!$L:$L,DATA!$O:$O,'SALES BY SYSTEM'!$A22,DATA!$M:$M,'SALES BY SYSTEM'!$O$3) -> 0 | L22: =SUMIFS('SALE BY STORE'!$Q$3:$Q$982,'SALE BY STORE'!$B$3:$B$982,'SALES BY SYSTEM'!$A22) -> 0 | M22: =SUMIFS(DATA!$L:$L,DATA!$O:$O,'SALES BY SYSTEM'!$A22,DATA!$M:$M,'SALES BY SYSTEM'!$O$4) -> 0
A23: BACH HOA BUU DIEN | C23: =SUMIFS('SALE BY STORE'!$H$3:$H$982,'SALE BY STORE'!$B$3:$B$982,'SALES BY SYSTEM'!$A23) -> 0 | D23: =VALUE(SUM(G23,K23,I23,M23)) -> 0 | E23: =IFERROR(D23/C23,"") | F23: =SUMIFS('SALE BY STORE'!$K$3:$K$982,'SALE BY STORE'!$B$3:$B$982,'SALES BY SYSTEM'!$A23) -> 0 | G23: =SUMIFS(DATA!$L:$L,DATA!$O:$O,'SALES BY SYSTEM'!$A23,DATA!$M:$M,'SALES BY SYSTEM'!$O$1) -> 0 | H23: =SUMIFS('SALE BY STORE'!$N$3:$N$982,'SALE BY STORE'!$B$3:$B$982,'SALES BY SYSTEM'!$A23) -> 0 | I23: =SUMIFS(DATA!$L:$L,DATA!$O:$O,'SALES BY SYSTEM'!$A23,DATA!$M:$M,'SALES BY SYSTEM'!$O$2) -> 0 | J23: =SUMIFS('SALE BY STORE'!$T$3:$T$982,'SALE BY STORE'!$B$3:$B$982,'SALES BY SYSTEM'!$A23) -> 0 | K23: =SUMIFS(DATA!$L:$L,DATA!$O:$O,'SALES BY SYSTEM'!$A23,DATA!$M:$M,'SALES BY SYSTEM'!$O$3) -> 0 | L23: =SUMIFS('SALE BY STORE'!$Q$3:$Q$982,'SALE BY STORE'!$B$3:$B$982,'SALES BY SYSTEM'!$A23) -> 0 | M23: =SUMIFS(DATA!$L:$L,DATA!$O:$O,'SALES BY SYSTEM'!$A23,DATA!$M:$M,'SALES BY SYSTEM'!$O$4) -> 0
A24: CUA HANG NHAT | C24: =SUMIFS('SALE BY STORE'!$H$3:$H$982,'SALE BY STORE'!$B$3:$B$982,'SALES BY SYSTEM'!$A24) -> 435167.21 | D24: =VALUE(SUM(G24,K24,I24,M24)) -> 0 | E24: =IFERROR(D24/C24,"") -> 0 | F24: =SUMIFS('SALE BY STORE'!$K$3:$K$982,'SALE BY STORE'!$B$3:$B$982,'SALES BY SYSTEM'!$A24) -> 0 | G24: =SUMIFS(DATA!$L:$L,DATA!$O:$O,'SALES BY SYSTEM'!$A24,DATA!$M:$M,'SALES BY SYSTEM'!$O$1) -> 0 | H24: =SUMIFS('SALE BY STORE'!$N$3:$N$982,'SALE BY STORE'!$B$3:$B$982,'SALES BY SYSTEM'!$A24) -> 435167.21 | I24: =SUMIFS(DATA!$L:$L,DATA!$O:$O,'SALES BY SYSTEM'!$A24,DATA!$M:$M,'SALES BY SYSTEM'!$O$2) -> 0 | J24: =SUMIFS('SALE BY STORE'!$T$3:$T$982,'SALE BY STORE'!$B$3:$B$982,'SALES BY SYSTEM'!$A24) -> 0 | K24: =SUMIFS(DATA!$L:$L,DATA!$O:$O,'SALES BY SYSTEM'!$A24,DATA!$M:$M,'SALES BY SYSTEM'!$O$3) -> 0 | L24: =SUMIFS('SALE BY STORE'!$Q$3:$Q$982,'SALE BY STORE'!$B$3:$B$982,'SALES BY SYSTEM'!$A24) -> 0 | M24: =SUMIFS(DATA!$L:$L,DATA!$O:$O,'SALES BY SYSTEM'!$A24,DATA!$M:$M,'SALES BY SYSTEM'!$O$4) -> 0
A25: CUA HANG TIEN LOI BUI | C25: =SUMIFS('SALE BY STORE'!$H$3:$H$982,'SALE BY STORE'!$B$3:$B$982,'SALES BY SYSTEM'!$A25) -> 0 | D25: =VALUE(SUM(G25,K25,I25,M25)) -> 0 | E25: =IFERROR(D25/C25,"") | F25: =SUMIFS('SALE BY STORE'!$K$3:$K$982,'SALE BY STORE'!$B$3:$B$982,'SALES BY SYSTEM'!$A25) -> 0 | G25: =SUMIFS(DATA!$L:$L,DATA!$O:$O,'SALES BY SYSTEM'!$A25,DATA!$M:$M,'SALES BY SYSTEM'!$O$1) -> 0 | H25: =SUMIFS('SALE BY STORE'!$N$3:$N$982,'SALE BY STORE'!$B$3:$B$982,'SALES BY SYSTEM'!$A25) -> 0 | I25: =SUMIFS(DATA!$L:$L,DATA!$O:$O,'SALES BY SYSTEM'!$A25,DATA!$M:$M,'SALES BY SYSTEM'!$O$2) -> 0 | J25: =SUMIFS('SALE BY STORE'!$T$3:$T$982,'SALE BY STORE'!$B$3:$B$982,'SALES BY SYSTEM'!$A25) -> 0 | K25: =SUMIFS(DATA!$L:$L,DATA!$O:$O,'SALES BY SYSTEM'!$A25,DATA!$M:$M,'SALES BY SYSTEM'!$O$3) -> 0 | L25: =SUMIFS('SALE BY STORE'!$Q$3:$Q$982,'SALE BY STORE'!$B$3:$B$982,'SALES BY SYSTEM'!$A25) -> 0 | M25: =SUMIFS(DATA!$L:$L,DATA!$O:$O,'SALES BY SYSTEM'!$A25,DATA!$M:$M,'SALES BY SYSTEM'!$O$4) -> 0
A26: GENSHAI | C26: =SUMIFS('SALE BY STORE'!$H$3:$H$982,'SALE BY STORE'!$B$3:$B$982,'SALES BY SYSTEM'!$A26) -> 78645222 | D26: =VALUE(SUM(G26,K26,I26,M26)) -> 0 | E26: =IFERROR(D26/C26,"") -> 0 | F26: =SUMIFS('SALE BY STORE'!$K$3:$K$982,'SALE BY STORE'!$B$3:$B$982,'SALES BY SYSTEM'!$A26) -> 0 | G26: =SUMIFS(DATA!$L:$L,DATA!$O:$O,'SALES BY SYSTEM'!$A26,DATA!$M:$M,'SALES BY SYSTEM'!$O$1) -> 0 | H26: =SUMIFS('SALE BY STORE'!$N$3:$N$982,'SALE BY STORE'!$B$3:$B$982,'SALES BY SYSTEM'!$A26) -> 20888026 | I26: =SUMIFS(DATA!$L:$L,DATA!$O:$O,'SALES BY SYSTEM'!$A26,DATA!$M:$M,'SALES BY SYSTEM'!$O$2) -> 0 | J26: =SUMIFS('SALE BY STORE'!$T$3:$T$982,'SALE BY STORE'!$B$3:$B$982,'SALES BY SYSTEM'!$A26) -> 0 | K26: =SUMIFS(DATA!$L:$L,DATA!$O:$O,'SALES BY SYSTEM'!$A26,DATA!$M:$M,'SALES BY SYSTEM'!$O$3) -> 0 | L26: =SUMIFS('SALE BY STORE'!$Q$3:$Q$982,'SALE BY STORE'!$B$3:$B$982,'SALES BY SYSTEM'!$A26) -> 57757195 | M26: =SUMIFS(DATA!$L:$L,DATA!$O:$O,'SALES BY SYSTEM'!$A26,DATA!$M:$M,'SALES BY SYSTEM'!$O$4) -> 0
A27: J MART | C27: =SUMIFS('SALE BY STORE'!$H$3:$H$982,'SALE BY STORE'!$B$3:$B$982,'SALES BY SYSTEM'!$A27) -> 9644438.9 | D27: =VALUE(SUM(G27,K27,I27,M27)) -> 0 | E27: =IFERROR(D27/C27,"") -> 0 | F27: =SUMIFS('SALE BY STORE'!$K$3:$K$982,'SALE BY STORE'!$B$3:$B$982,'SALES BY SYSTEM'!$A27) -> 0 | G27: =SUMIFS(DATA!$L:$L,DATA!$O:$O,'SALES BY SYSTEM'!$A27,DATA!$M:$M,'SALES BY SYSTEM'!$O$1) -> 0 | H27: =SUMIFS('SALE BY STORE'!$N$3:$N$982,'SALE BY STORE'!$B$3:$B$982,'SALES BY SYSTEM'!$A27) -> 2175836.1 | I27: =SUMIFS(DATA!$L:$L,DATA!$O:$O,'SALES BY SYSTEM'!$A27,DATA!$M:$M,'SALES BY SYSTEM'!$O$2) -> 0 | J27: =SUMIFS('SALE BY STORE'!$T$3:$T$982,'SALE BY STORE'!$B$3:$B$982,'SALES BY SYSTEM'!$A27) -> 0 | K27: =SUMIFS(DATA!$L:$L,DATA!$O:$O,'SALES BY SYSTEM'!$A27,DATA!$M:$M,'SALES BY SYSTEM'!$O$3) -> 0 | L27: =SUMIFS('SALE BY STORE'!$Q$3:$Q$982,'SALE BY STORE'!$B$3:$B$982,'SALES BY SYSTEM'!$A27) -> 7468602.9 | M27: =SUMIFS(DATA!$L:$L,DATA!$O:$O,'SALES BY SYSTEM'!$A27,DATA!$M:$M,'SALES BY SYSTEM'!$O$4) -> 0
A28: JOLYMART | C28: =SUMIFS('SALE BY STORE'!$H$3:$H$982,'SALE BY STORE'!$B$3:$B$982,'SALES BY SYSTEM'!$A28) -> 0 | D28: =VALUE(SUM(G28,K28,I28,M28)) -> 0 | E28: =IFERROR(D28/C28,"") | F28: =SUMIFS('SALE BY STORE'!$K$3:$K$982,'SALE BY STORE'!$B$3:$B$982,'SALES BY SYSTEM'!$A28) -> 0 | G28: =SUMIFS(DATA!$L:$L,DATA!$O:$O,'SALES BY SYSTEM'!$A28,DATA!$M:$M,'SALES BY SYSTEM'!$O$1) -> 0 | H28: =SUMIFS('SALE BY STORE'!$N$3:$N$982,'SALE BY STORE'!$B$3:$B$982,'SALES BY SYSTEM'!$A28) -> 0 | I28: =SUMIFS(DATA!$L:$L,DATA!$O:$O,'SALES BY SYSTEM'!$A28,DATA!$M:$M,'SALES BY SYSTEM'!$O$2) -> 0 | J28: =SUMIFS('SALE BY STORE'!$T$3:$T$982,'SALE BY STORE'!$B$3:$B$982,'SALES BY SYSTEM'!$A28) -> 0 | K28: =SUMIFS(DATA!$L:$L,DATA!$O:$O,'SALES BY SYSTEM'!$A28,DATA!$M:$M,'SALES BY SYSTEM'!$O$3) -> 0 | L28: =SUMIFS('SALE BY STORE'!$Q$3:$Q$982,'SALE BY STORE'!$B$3:$B$982,'SALES BY SYSTEM'!$A28) -> 0 | M28: =SUMIFS(DATA!$L:$L,DATA!$O:$O,'SALES BY SYSTEM'!$A28,DATA!$M:$M,'SALES BY SYSTEM'!$O$4) -> 0
A29: KING FOOD | C29: =SUMIFS('SALE BY STORE'!$H$3:$H$982,'SALE BY STORE'!$B$3:$B$982,'SALES BY SYSTEM'!$A29) -> 40828362 | D29: =VALUE(SUM(G29,K29,I29,M29)) -> 0 | E29: =IFERROR(D29/C29,"") -> 0 | F29: =SUMIFS('SALE BY STORE'!$K$3:$K$982,'SALE BY STORE'!$B$3:$B$982,'SALES BY SYSTEM'!$A29) -> 0 | G29: =SUMIFS(DATA!$L:$L,DATA!$O:$O,'SALES BY SYSTEM'!$A29,DATA!$M:$M,'SALES BY SYSTEM'!$O$1) -> 0 | H29: =SUMIFS('SALE BY STORE'!$N$3:$N$982,'SALE BY STORE'!$B$3:$B$982,'SALES BY SYSTEM'!$A29) -> 0 | I29: =SUMIFS(DATA!$L:$L,DATA!$O:$O,'SALES BY SYSTEM'!$A29,DATA!$M:$M,'SALES BY SYSTEM'!$O$2) -> 0 | J29: =SUMIFS('SALE BY STORE'!$T$3:$T$982,'SALE BY STORE'!$B$3:$B$982,'SALES BY SYSTEM'!$A29) -> 0 | K29: =SUMIFS(DATA!$L:$L,DATA!$O:$O,'SALES BY SYSTEM'!$A29,DATA!$M:$M,'SALES BY SYSTEM'!$O$3) -> 0 | L29: =SUMIFS('SALE BY STORE'!$Q$3:$Q$982,'SALE BY STORE'!$B$3:$B$982,'SALES BY SYSTEM'!$A29) -> 40828362 | M29: =SUMIFS(DATA!$L:$L,DATA!$O:$O,'SALES BY SYSTEM'!$A29,DATA!$M:$M,'SALES BY SYSTEM'!$O$4) -> 0
A30: AN NAM | C30: =SUMIFS('SALE BY STORE'!$H$3:$H$982,'SALE BY STORE'!$B$3:$B$982,'SALES BY SYSTEM'!$A30) -> 61540201 | D30: =VALUE(SUM(G30,K30,I30,M30)) -> 0 | E30: =IFERROR(D30/C30,"") -> 0 | F30: =SUMIFS('SALE BY STORE'!$K$3:$K$982,'SALE BY STORE'!$B$3:$B$982,'SALES BY SYSTEM'!$A30) -> 0 | G30: =SUMIFS(DATA!$L:$L,DATA!$O:$O,'SALES BY SYSTEM'!$A30,DATA!$M:$M,'SALES BY SYSTEM'!$O$1) -> 0 | H30: =SUMIFS('SALE BY STORE'!$N$3:$N$982,'SALE BY STORE'!$B$3:$B$982,'SALES BY SYSTEM'!$A30) -> 11749515 | I30: =SUMIFS(DATA!$L:$L,DATA!$O:$O,'SALES BY SYSTEM'!$A30,DATA!$M:$M,'SALES BY SYSTEM'!$O$2) -> 0 | J30: =SUMIFS('SALE BY STORE'!$T$3:$T$982,'SALE BY STORE'!$B$3:$B$982,'SALES BY SYSTEM'!$A30) -> 0 | K30: =SUMIFS(DATA!$L:$L,DATA!$O:$O,'SALES BY SYSTEM'!$A30,DATA!$M:$M,'SALES BY SYSTEM'!$O$3) -> 0 | L30: =SUMIFS('SALE BY STORE'!$Q$3:$Q$982,'SALE BY STORE'!$B$3:$B$982,'SALES BY SYSTEM'!$A30) -> 49790686 | M30: =SUMIFS(DATA!$L:$L,DATA!$O:$O,'SALES BY SYSTEM'!$A30,DATA!$M:$M,'SALES BY SYSTEM'!$O$4) -> 0
A31: MINISTOP G7 | C31: =SUMIFS('SALE BY STORE'!$H$3:$H$982,'SALE BY STORE'!$B$3:$B$982,'SALES BY SYSTEM'!$A31) -> 0 | D31: =VALUE(SUM(G31,K31,I31,M31)) -> 0 | E31: =IFERROR(D31/C31,"") | F31: =SUMIFS('SALE BY STORE'!$K$3:$K$982,'SALE BY STORE'!$B$3:$B$982,'SALES BY SYSTEM'!$A31) -> 0 | G31: =SUMIFS(DATA!$L:$L,DATA!$O:$O,'SALES BY SYSTEM'!$A31,DATA!$M:$M,'SALES BY SYSTEM'!$O$1) -> 0 | H31: =SUMIFS('SALE BY STORE'!$N$3:$N$982,'SALE BY STORE'!$B$3:$B$982,'SALES BY SYSTEM'!$A31) -> 0 | I31: =SUMIFS(DATA!$L:$L,DATA!$O:$O,'SALES BY SYSTEM'!$A31,DATA!$M:$M,'SALES BY SYSTEM'!$O$2) -> 0 | J31: =SUMIFS('SALE BY STORE'!$T$3:$T$982,'SALE BY STORE'!$B$3:$B$982,'SALES BY SYSTEM'!$A31) -> 0 | K31: =SUMIFS(DATA!$L:$L,DATA!$O:$O,'SALES BY SYSTEM'!$A31,DATA!$M:$M,'SALES BY SYSTEM'!$O$3) -> 0 | L31: =SUMIFS('SALE BY STORE'!$Q$3:$Q$982,'SALE BY STORE'!$B$3:$B$982,'SALES BY SYSTEM'!$A31) -> 0 | M31: =SUMIFS(DATA!$L:$L,DATA!$O:$O,'SALES BY SYSTEM'!$A31,DATA!$M:$M,'SALES BY SYSTEM'!$O$4) -> 0
A32: K MART | C32: =SUMIFS('SALE BY STORE'!$H$3:$H$982,'SALE BY STORE'!$B$3:$B$982,'SALES BY SYSTEM'!$A32) -> 9644438.9 | D32: =VALUE(SUM(G32,K32,I32,M32)) -> 0 | E32: =IFERROR(D32/C32,"") -> 0 | F32: =SUMIFS('SALE BY STORE'!$K$3:$K$982,'SALE BY STORE'!$B$3:$B$982,'SALES BY SYSTEM'!$A32) -> 0 | G32: =SUMIFS(DATA!$L:$L,DATA!$O:$O,'SALES BY SYSTEM'!$A32,DATA!$M:$M,'SALES BY SYSTEM'!$O$1) -> 0 | H32: =SUMIFS('SALE BY STORE'!$N$3:$N$982,'SALE BY STORE'!$B$3:$B$982,'SALES BY SYSTEM'!$A32) -> 2175836.1 | I32: =SUMIFS(DATA!$L:$L,DATA!$O:$O,'SALES BY SYSTEM'!$A32,DATA!$M:$M,'SALES BY SYSTEM'!$O$2) -> 0 | J32: =SUMIFS('SALE BY STORE'!$T$3:$T$982,'SALE BY STORE'!$B$3:$B$982,'SALES BY SYSTEM'!$A32) -> 0 | K32: =SUMIFS(DATA!$L:$L,DATA!$O:$O,'SALES BY SYSTEM'!$A32,DATA!$M:$M,'SALES BY SYSTEM'!$O$3) -> 0 | L32: =SUMIFS('SALE BY STORE'!$Q$3:$Q$982,'SALE BY STORE'!$B$3:$B$982,'SALES BY SYSTEM'!$A32) -> 7468602.9 | M32: =SUMIFS(DATA!$L:$L,DATA!$O:$O,'SALES BY SYSTEM'!$A32,DATA!$M:$M,'SALES BY SYSTEM'!$O$4) -> 0
A33: LOTTE | C33: =SUMIFS('SALE BY STORE'!$H$3:$H$982,'SALE BY STORE'!$B$3:$B$982,'SALES BY SYSTEM'!$A33) -> 3.3209643e+08 | D33: =VALUE(SUM(G33,K33,I33,M33)) -> 0 | E33: =IFERROR(D33/C33,"") -> 0 | F33: =SUMIFS('SALE BY STORE'!$K$3:$K$982,'SALE BY STORE'!$B$3:$B$982,'SALES BY SYSTEM'!$A33) -> 0 | G33: =SUMIFS(DATA!$L:$L,DATA!$O:$O,'SALES BY SYSTEM'!$A33,DATA!$M:$M,'SALES BY SYSTEM'!$O$1) -> 0 | H33: =SUMIFS('SALE BY STORE'!$N$3:$N$982,'SALE BY STORE'!$B$3:$B$982,'SALES BY SYSTEM'!$A33) -> 34072280 | I33: =SUMIFS(DATA!$L:$L,DATA!$O:$O,'SALES BY SYSTEM'!$A33,DATA!$M:$M,'SALES BY SYSTEM'!$O$2) -> 0 | J33: =SUMIFS('SALE BY STORE'!$T$3:$T$982,'SALE BY STORE'!$B$3:$B$982,'SALES BY SYSTEM'!$A33) -> 0 | K33: =SUMIFS(DATA!$L:$L,DATA!$O:$O,'SALES BY SYSTEM'!$A33,DATA!$M:$M,'SALES BY SYSTEM'!$O$3) -> 0 | L33: =SUMIFS('SALE BY STORE'!$Q$3:$Q$982,'SALE BY STORE'!$B$3:$B$982,'SALES BY SYSTEM'!$A33) -> 2.9802414e+08 | M33: =SUMIFS(DATA!$L:$L,DATA!$O:$O,'SALES BY SYSTEM'!$A33,DATA!$M:$M,'SALES BY SYSTEM'!$O$4) -> 0
... A37: LONG CHAU | C37: =SUMIFS('SALE BY STORE'!$H$3:$H$982,'SALE BY STORE'!$B$3:$B$982,'SALES BY SYSTEM'!$A37) -> 5.1025427e+08 | D37: =VALUE(SUM(G37,K37,I37,M37)) -> 0 | E37: =IFERROR(D37/C37,"") -> 0 | F37: =SUMIFS('SALE BY STORE'!$K$3:$K$982,'SALE BY STORE'!$B$3:$B$982,'SALES BY SYSTEM'!$A37) -> 0 | G37: =SUMIFS(DATA!$L:$L,DATA!$O:$O,'SALES BY SYSTEM'!$A37,DATA!$M:$M,'SALES BY SYSTEM'!$O$1) -> 0 | H37: =SUMIFS('SALE BY STORE'!$N$3:$N$982,'SALE BY STORE'!$B$3:$B$982,'SALES BY SYSTEM'!$A37) -> 87033443 | I37: =SUMIFS(DATA!$L:$L,DATA!$O:$O,'SALES BY SYSTEM'!$A37,DATA!$M:$M,'SALES BY SYSTEM'!$O$2) -> 0 | J37: =SUMIFS('SALE BY STORE'!$T$3:$T$982,'SALE BY STORE'!$B$3:$B$982,'SALES BY SYSTEM'!$A37) -> 0 | K37: =SUMIFS(DATA!$L:$L,DATA!$O:$O,'SALES BY SYSTEM'!$A37,DATA!$M:$M,'SALES BY SYSTEM'!$O$3) -> 0 | L37: =SUMIFS('SALE BY STORE'!$Q$3:$Q$982,'SALE BY STORE'!$B$3:$B$982,'SALES BY SYSTEM'!$A37) -> 4.2322083e+08 | M37: =SUMIFS(DATA!$L:$L,DATA!$O:$O,'SALES BY SYSTEM'!$A37,DATA!$M:$M,'SALES BY SYSTEM'!$O$4) -> 0
A38: MEDICARE | B38: 86 | C38: =SUMIFS('SALE BY STORE'!$H$3:$H$982,'SALE BY STORE'!$B$3:$B$982,'SALES BY SYSTEM'!$A38) -> 0 | D38: =VALUE(SUM(G38,K38,I38,M38)) -> 0 | E38: =IFERROR(D38/C38,"") | F38: =SUMIFS('SALE BY STORE'!$K$3:$K$982,'SALE BY STORE'!$B$3:$B$982,'SALES BY SYSTEM'!$A38) -> 0 | G38: =SUMIFS(DATA!$L:$L,DATA!$O:$O,'SALES BY SYSTEM'!$A38,DATA!$M:$M,'SALES BY SYSTEM'!$O$1) -> 0 | H38: =SUMIFS('SALE BY STORE'!$N$3:$N$982,'SALE BY STORE'!$B$3:$B$982,'SALES BY SYSTEM'!$A38) -> 0 | I38: =SUMIFS(DATA!$L:$L,DATA!$O:$O,'SALES BY SYSTEM'!$A38,DATA!$M:$M,'SALES BY SYSTEM'!$O$2) -> 0 | J38: =SUMIFS('SALE BY STORE'!$T$3:$T$982,'SALE BY STORE'!$B$3:$B$982,'SALES BY SYSTEM'!$A38) -> 0 | K38: =SUMIFS(DATA!$L:$L,DATA!$O:$O,'SALES BY SYSTEM'!$A38,DATA!$M:$M,'SALES BY SYSTEM'!$O$3) -> 0 | L38: =SUMIFS('SALE BY STORE'!$Q$3:$Q$982,'SALE BY STORE'!$B$3:$B$982,'SALES BY SYSTEM'!$A38) -> 0 | M38: =SUMIFS(DATA!$L:$L,DATA!$O:$O,'SALES BY SYSTEM'!$A38,DATA!$M:$M,'SALES BY SYSTEM'!$O$4) -> 0
A39: FAMIMART | C39: =SUMIFS('SALE BY STORE'!$H$3:$H$982,'SALE BY STORE'!$B$3:$B$982,'SALES BY SYSTEM'!$A39) -> 0 | D39: =VALUE(SUM(G39,K39,I39,M39)) -> 0 | E39: =IFERROR(D39/C39,"") | F39: =SUMIFS('SALE BY STORE'!$K$3:$K$982,'SALE BY STORE'!$B$3:$B$982,'SALES BY SYSTEM'!$A39) -> 0 | G39: =SUMIFS(DATA!$L:$L,DATA!$O:$O,'SALES BY SYSTEM'!$A39,DATA!$M:$M,'SALES BY SYSTEM'!$O$1) -> 0 | H39: =SUMIFS('SALE BY STORE'!$N$3:$N$982,'SALE BY STORE'!$B$3:$B$982,'SALES BY SYSTEM'!$A39) -> 0 | I39: =SUMIFS(DATA!$L:$L,DATA!$O:$O,'SALES BY SYSTEM'!$A39,DATA!$M:$M,'SALES BY SYSTEM'!$O$2) -> 0 | J39: =SUMIFS('SALE BY STORE'!$T$3:$T$982,'SALE BY STORE'!$B$3:$B$982,'SALES BY SYSTEM'!$A39) -> 0 | K39: =SUMIFS(DATA!$L:$L,DATA!$O:$O,'SALES BY SYSTEM'!$A39,DATA!$M:$M,'SALES BY SYSTEM'!$O$3) -> 0 | L39: =SUMIFS('SALE BY STORE'!$Q$3:$Q$982,'SALE BY STORE'!$B$3:$B$982,'SALES BY SYSTEM'!$A39) -> 0 | M39: =SUMIFS(DATA!$L:$L,DATA!$O:$O,'SALES BY SYSTEM'!$A39,DATA!$M:$M,'SALES BY SYSTEM'!$O$4) -> 0
A40: FRUITS AND MORE | C40: =SUMIFS('SALE BY STORE'!$H$3:$H$982,'SALE BY STORE'!$B$3:$B$982,'SALES BY SYSTEM'!$A40) -> 0 | D40: =VALUE(SUM(G40,K40,I40,M40)) -> 0 | E40: =IFERROR(D40/C40,"") | F40: =SUMIFS('SALE BY STORE'!$K$3:$K$982,'SALE BY STORE'!$B$3:$B$982,'SALES BY SYSTEM'!$A40) -> 0 | G40: =SUMIFS(DATA!$L:$L,DATA!$O:$O,'SALES BY SYSTEM'!$A40,DATA!$M:$M,'SALES BY SYSTEM'!$O$1) -> 0 | H40: =SUMIFS('SALE BY STORE'!$N$3:$N$982,'SALE BY STORE'!$B$3:$B$982,'SALES BY SYSTEM'!$A40) -> 0 | I40: =SUMIFS(DATA!$L:$L,DATA!$O:$O,'SALES BY SYSTEM'!$A40,DATA!$M:$M,'SALES BY SYSTEM'!$O$2) -> 0 | J40: =SUMIFS('SALE BY STORE'!$T$3:$T$982,'SALE BY STORE'!$B$3:$B$982,'SALES BY SYSTEM'!$A40) -> 0 | K40: =SUMIFS(DATA!$L:$L,DATA!$O:$O,'SALES BY SYSTEM'!$A40,DATA!$M:$M,'SALES BY SYSTEM'!$O$3) -> 0 | L40: =SUMIFS('SALE BY STORE'!$Q$3:$Q$982,'SALE BY STORE'!$B$3:$B$982,'SALES BY SYSTEM'!$A40) -> 0 | M40: =SUMIFS(DATA!$L:$L,DATA!$O:$O,'SALES BY SYSTEM'!$A40,DATA!$M:$M,'SALES BY SYSTEM'!$O$4) -> 0
A41: NHANH NHANH | C41: =SUMIFS('SALE BY STORE'!$H$3:$H$982,'SALE BY STORE'!$B$3:$B$982,'SALES BY SYSTEM'!$A41) -> 0 | D41: =VALUE(SUM(G41,K41,I41,M41)) -> 0 | E41: =IFERROR(D41/C41,"") | F41: =SUMIFS('SALE BY STORE'!$K$3:$K$982,'SALE BY STORE'!$B$3:$B$982,'SALES BY SYSTEM'!$A41) -> 0 | G41: =SUMIFS(DATA!$L:$L,DATA!$O:$O,'SALES BY SYSTEM'!$A41,DATA!$M:$M,'SALES BY SYSTEM'!$O$1) -> 0 | H41: =SUMIFS('SALE BY STORE'!$N$3:$N$982,'SALE BY STORE'!$B$3:$B$982,'SALES BY SYSTEM'!$A41) -> 0 | I41: =SUMIFS(DATA!$L:$L,DATA!$O:$O,'SALES BY SYSTEM'!$A41,DATA!$M:$M,'SALES BY SYSTEM'!$O$2) -> 0 | J41: =SUMIFS('SALE BY STORE'!$T$3:$T$982,'SALE BY STORE'!$B$3:$B$982,'SALES BY SYSTEM'!$A41) -> 0 | K41: =SUMIFS(DATA!$L:$L,DATA!$O:$O,'SALES BY SYSTEM'!$A41,DATA!$M:$M,'SALES BY SYSTEM'!$O$3) -> 0 | L41: =SUMIFS('SALE BY STORE'!$Q$3:$Q$982,'SALE BY STORE'!$B$3:$B$982,'SALES BY SYSTEM'!$A41) -> 0 | M41: =SUMIFS(DATA!$L:$L,DATA!$O:$O,'SALES BY SYSTEM'!$A41,DATA!$M:$M,'SALES BY SYSTEM'!$O$4) -> 0
A42: PHAM HUY ANH | C42: =SUMIFS('SALE BY STORE'!$H$3:$H$982,'SALE BY STORE'!$B$3:$B$982,'SALES BY SYSTEM'!$A42) -> 0 | D42: =VALUE(SUM(G42,K42,I42,M42)) -> 0 | E42: =IFERROR(D42/C42,"") | F42: =SUMIFS('SALE BY STORE'!$K$3:$K$982,'SALE BY STORE'!$B$3:$B$982,'SALES BY SYSTEM'!$A42) -> 0 | G42: =SUMIFS(DATA!$L:$L,DATA!$O:$O,'SALES BY SYSTEM'!$A42,DATA!$M:$M,'SALES BY SYSTEM'!$O$1) -> 0 | H42: =SUMIFS('SALE BY STORE'!$N$3:$N$982,'SALE BY STORE'!$B$3:$B$982,'SALES BY SYSTEM'!$A42) -> 0 | I42: =SUMIFS(DATA!$L:$L,DATA!$O:$O,'SALES BY SYSTEM'!$A42,DATA!$M:$M,'SALES BY SYSTEM'!$O$2) -> 0 | J42: =SUMIFS('SALE BY STORE'!$T$3:$T$982,'SALE BY STORE'!$B$3:$B$982,'SALES BY SYSTEM'!$A42) -> 0 | K42: =SUMIFS(DATA!$L:$L,DATA!$O:$O,'SALES BY SYSTEM'!$A42,DATA!$M:$M,'SALES BY SYSTEM'!$O$3) -> 0 | L42: =SUMIFS('SALE BY STORE'!$Q$3:$Q$982,'SALE BY STORE'!$B$3:$B$982,'SALES BY SYSTEM'!$A42) -> 0 | M42: =SUMIFS(DATA!$L:$L,DATA!$O:$O,'SALES BY SYSTEM'!$A42,DATA!$M:$M,'SALES BY SYSTEM'!$O$4) -> 0
A43: KING KONG MART | B43: 1 | C43: =SUMIFS('SALE BY STORE'!$H$3:$H$982,'SALE BY STORE'!$B$3:$B$982,'SALES BY SYSTEM'!$A43) -> 6223835.7 | D43: =VALUE(SUM(G43,K43,I43,M43)) -> 0 | E43: =IFERROR(D43/C43,"") -> 0 | F43: =SUMIFS('SALE BY STORE'!$K$3:$K$982,'SALE BY STORE'!$B$3:$B$982,'SALES BY SYSTEM'!$A43) -> 0 | G43: =SUMIFS(DATA!$L:$L,DATA!$O:$O,'SALES BY SYSTEM'!$A43,DATA!$M:$M,'SALES BY SYSTEM'!$O$1) -> 0 | H43: =SUMIFS('SALE BY STORE'!$N$3:$N$982,'SALE BY STORE'!$B$3:$B$982,'SALES BY SYSTEM'!$A43) -> 0 | I43: =SUMIFS(DATA!$L:$L,DATA!$O:$O,'SALES BY SYSTEM'!$A43,DATA!$M:$M,'SALES BY SYSTEM'!$O$2) -> 0 | J43: =SUMIFS('SALE BY STORE'!$T$3:$T$982,'SALE BY STORE'!$B$3:$B$982,'SALES BY SYSTEM'!$A43) -> 0 | K43: =SUMIFS(DATA!$L:$L,DATA!$O:$O,'SALES BY SYSTEM'!$A43,DATA!$M:$M,'SALES BY SYSTEM'!$O$3) -> 0 | L43: =SUMIFS('SALE BY STORE'!$Q$3:$Q$982,'SALE BY STORE'!$B$3:$B$982,'SALES BY SYSTEM'!$A43) -> 6223835.7 | M43: =SUMIFS(DATA!$L:$L,DATA!$O:$O,'SALES BY SYSTEM'!$A43,DATA!$M:$M,'SALES BY SYSTEM'!$O$4) -> 0
...

Sheet CUSTOMER
A1: TEN DON VI | B1: HE THONG | C1: SYSTEM CODE | D1: KA | E1: SUP | F1: SALE | G1: PG | H1: QUAN | I1: VUNG MIEN | J1: TINH/THANH
A2: HO KINH DOANH 3S PHAN THIET | B2: 3S PHAN THIET | C2: 3S_PTHIET | D2: KA HCM1 | E2: VACANCY | F2: VACANCY | G2: "NO PG"
A3: A STORE AN GIANG | B3: A STORE | C3: 6322 | D3: KA HCM1 | E3: VACANCY | F3: VACANCY | G3: "NO PG" | I3: AN GIANG | J3: DONG BANG SONG CUU LONG
A4: AB BEAUTY WORLD | B4: ABBW | C4: AB_PART | D4: KA HCM1 | E4: VACANCY | F4: VACANCY | G4: "NO PG" | I4: TP HCM | J4: HCM
A5: AB BEAUTY WORLD LE DAI HANH | B5: ABBW | C5: AB_LDH | D5: KA HCM1 | E5: VACANCY | F5: VACANCY | G5: "NO PG" | I5: TP HCM | J5: HCM
A6: AB BEAUTY WORLD LE VAN SY | B6: ABBW | C6: AB_LVS | D6: KA HCM1 | E6: VACANCY | F6: VACANCY | G6: "NO PG" | I6: TP HCM | J6: HCM
A7: AB BEAUTY WORLD LUY BAN BICH | B7: ABBW | C7: AB_LBB | D7: KA HCM1 | E7: VACANCY | F7: VACANCY | G7: "NO PG" | I7: TP HCM | J7: HCM
A8: AB BEAUTY WORLD MA LO | B8: ABBW | C8: AB_MALO | D8: KA HCM1 | E8: VACANCY | F8: VACANCY | G8: "NO PG" | I8: TP HCM | J8: HCM
A9: AB BEAUTY WORLD NGUYEN THI THAP | B9: ABBW | C9: AB_NTTHAP | D9: KA HCM1 | E9: VACANCY | F9: VACANCY | G9: "NO PG" | I9: TP HCM | J9: HCM
A10: AB BEAUTY WORLD PHAN DANG LUU | B10: ABBW | C10: AB_PDL | D10: KA HCM1 | E10: VACANCY | F10: VACANCY | G10: "NO PG" | I10: TP HCM | J10: HCM
A11: ACE HOME CELADON | B11: ACE | C11: ACE_HOME_CEL | D11: KA HCM1 | E11: LE NAM PHUONG | F11: VACANCY | G11: "NO PG"
A12: ACE HOME SU VAN HANH | B12: ACE | C12: ACE_HOME_SVH | D12: KA HCM1 | E12: LE NAM PHUONG | F12: VACANCY | G12: "NO PG"
A13: ACE CELADON | B13: ACE | C13: ACE_CELADON | D13: KA HCM1 | E13: LE NAM PHUONG | F13: VU THUY MINH THAO | G13: "NO PG"
A14: ACE SONG HANH | B14: ACE | C14: ACE_SH | D14: KA HCM1 | E14: LE NAM PHUONG | F14: VU THUY MINH THAO | G14: "NO PG" | I14: TP HCM | J14: HCM
A15: ACE SU VAN HANH | B15: ACE | C15: ACE_SVH | D15: KA HCM1 | E15: LE NAM PHUONG | F15: VU THUY MINH THAO | G15: "NO PG" | I15: TP HCM | J15: HCM
A16: ACE VIVOCITY | B16: ACE | C16: ACE_VIVO | D16: KA HCM1 | E16: LE NAM PHUONG | F16: VU THUY MINH THAO | G16: "NO PG"
A17: AEON BINH DUONG | B17: AEON | C17: AEON_BDUONG_RDC | D17: KA HCM1 | E17: LE NAM PHUONG | F17: VACANCY | G17: "NO PG" | I17: BINH DUONG | J17: MIEN DONG NAM BO
A18: AEON BINH TAN | B18: AEON | C18: AEON_BTAN_RDC | D18: KA HCM1 | E18: LE NAM PHUONG | F18: VACANCY | G18: "NO PG" | I18: TP HCM | J18: HCM
A19: AEON HA DONG | B19: AEON | C19: AEON_HDONG_RDC | D19: KA HCM1 | E19: LE NAM PHUONG | F19: LE THI HONG DIEP | G19: "NO PG" | I19: HA NOI | J19: MIEN BAC
A20: AEON HAI PHONG | B20: AEON | C20: AEON_HPHONG_RDC | D20: KA HCM1 | E20: LE NAM PHUONG | F20: VACANCY | G20: "NO PG" | I20: HAI PHONG | J20: MIEN BAC
A21: AEON LONG BIEN | B21: AEON | C21: AEON_LBIEN_RDC | D21: KA HCM1 | E21: LE NAM PHUONG | F21: LE THI HONG DIEP | G21: "NO PG" | I21: HA NOI | J21: MIEN BAC
A22: AEON NEWTON | B22: AEON | C22: AEON_GBNEWTON_RDC | D22: KA HCM1 | E22: LE NAM PHUONG | F22: VACANCY | G22: "NO PG" | I22: HAI PHONG | J22: MIEN BAC
A23: AEON TAN PHU | B23: AEON | C23: AEON_TPHU_RDC | D23: KA HCM1 | E23: LE NAM PHUONG | F23: VU THUY MINH THAO | G23: "NO PG" | I23: TP HCM | J23: HCM
A24: AEON CITI B&B CONIC | B24: AEON CITI | C24: CITI_CONIC | D24: KA HCM1 | E24: LE NAM PHUONG | F24: "NO SALE" | G24: "NO PG" | I24: TP HCM | J24: HCM
A25: AEON CITI BCA QUAN 2 | B25: AEON CITI | C25: CITI_BCAN | D25: KA HCM1 | E25: LE NAM PHUONG | F25: "NO SALE" | G25: "NO PG" | I25: TP HCM | J25: HCM
A26: AEON CITI BINH DUONG | B26: AEON CITI | C26: CITI_BDUONG | D26: KA HCM1 | E26: LE NAM PHUONG | F26: "NO SALE" | G26: "NO PG" | I26: BINH DUONG | J26: MIEN DONG NAM BO
A27: AEON CITI BINH TAN | B27: AEON CITI | C27: CITI_BTAN | D27: KA HCM1 | E27: LE NAM PHUONG | F27: "NO SALE" | G27: "NO PG" | I27: TP HCM | J27: HCM
A28: AEON CITI CAO THANG | B28: AEON CITI | C28: CITI_CTHANG | D28: KA HCM1 | E28: LE NAM PHUONG | F28: "NO SALE" | G28: "NO PG" | I28: TP HCM | J28: HCM
... A47: AEON CITI TROPIC QUAN 2 | B47: AEON CITI | C47: CITI_TROPIC | D47: KA HCM1 | E47: LE NAM PHUONG | F47: "NO SALE" | G47: "NO PG" | I47: TP HCM | J47: HCM
A48: AEON CITI ORCH | B48: AEON CITI | C48: CITI_ORCH | D48: KA HCM1 | E48: LE NAM PHUONG | F48: VACANCY | G48: "NO PG"
A49: AN NAM FELIZ | B49: AN NAM | C49: SD_FELIZ | D49: KA HCM1 | E49: TRAN THI THAO NGUYEN | F49: NGUYEN THI MUON | G49: "NO PG"
A50: AN NAM HAI BA TRUNG | B50: AN NAM | C50: SD_HBT | D50: KA HCM1 | E50: TRAN THI THAO NGUYEN | F50: NGUYEN THI MUON | G50: "NO PG" | I50: TP HCM | J50: HCM
A51: AN NAM LANDMART 81 | B51: AN NAM | C51: SD_LAND81 | D51: KA HCM1 | E51: TRAN THI THAO NGUYEN | F51: NGUYEN THI MUON | G51: "NO PG" | I51: TP HCM | J51: HCM
A52: AN NAM LE LOI | B52: AN NAM | C52: SD_LLOI | D52: KA HCM1 | E52: TRAN THI THAO NGUYEN | F52: NGUYEN THI MUON | G52: "NO PG" | I52: TP HCM | J52: HCM
A53: AN NAM LONG BIEN | B53: AN NAM | C53: SD_LBIEN | D53: KA HCM1 | E53: TRAN THI THAO NGUYEN | F53: LE THI HONG DIEP | G53: "NO PG"
A54: AN NAM NGUYEN DUC CANH | B54: AN NAM | C54: SD_NDC | D54: KA HCM1 | E54: TRAN THI THAO NGUYEN | F54: NGUYEN THI MUON | G54: "NO PG" | I54: TP HCM | J54: HCM
A55: AN NAM NGUYEN HUU CANH | B55: AN NAM | C55: SD_NHC | D55: KA HCM1 | E55: TRAN THI THAO NGUYEN | F55: NGUYEN THI MUON | G55: "NO PG" | I55: TP HCM | J55: HCM
A56: AN NAM NGUYEN LUONG BANG | B56: AN NAM | C56: SD_NLB | D56: KA HCM1 | E56: TRAN THI THAO NGUYEN | F56: NGUYEN THI MUON | G56: "NO PG"
A57: AN NAM NGUYEN VAN TROI | B57: AN NAM | C57: SD_NVT | D57: KA HCM1 | E57: TRAN THI THAO NGUYEN | F57: NGUYEN THI MUON | G57: "NO PG"
A58: AN NAM SONG HANH | B58: AN NAM | C58: SD_SH | D58: KA HCM1 | E58: TRAN THI THAO NGUYEN | F58: NGUYEN THI MUON | G58: "NO PG" | I58: TP HCM | J58: HCM
...

Sheet Sheet5
A1: MA KH | B1: HỆ THỐNG | C1: STORE
A2: ACE_SVH | B2: ACE | C2: ACE SU VAN HANH
A3: ACE_SH | B3: ACE | C3: ACE SONG HANH
A4: 6442 | B4: FOODSMART | C4: FOODSMART
A5: AEON_BDUONG_RDC | B5: AEON | C5: AEON BINH DUONG
A6: AEON_BTAN_RDC | B6: AEON | C6: AEON BINH TAN
A7: AEON_HDONG_RDC | B7: AEON | C7: AEON HA DONG
A8: AEON_HPHONG_RDC | B8: AEON | C8: AEON HAI PHONG
A9: AEON_LBIEN_RDC | B9: AEON | C9: AEON LONG BIEN
A10: AEON_TPHU_RDC | B10: AEON | C10: AEON TAN PHU
A11: AEON_GBNEWTON_RDC | B11: AEON | C11: AEON NEWTON
A12: SD_FELIZ | B12: AN NAM | C12: AN NAM FELIZ
... A413: 6441_PEGASUITE | B413: HASHTAG ECOS | C413: CTY CP HASHTAG ECOS PEGASUITE
A414: 4317 | B414: BIG C | C414: B'S MART
A415: 6485 | B415: UBG | C415: CÔNG TY CỔ PHẦN ĐẦU TƯ QUỐC TẾ UBG
A416: CP_CMT8 | B416: CAO PHONG | C416: CAO PHONG CACH MANG THANG 8
A417: CP_HD | B417: CAO PHONG | C417: CAO PHONG HOANG DIEU
A418: CP_HV | B418: CAO PHONG | C418: CAO PHONG HUNG VUONG
A419: CP_LDC | B419: CAO PHONG | C419: CAO PHONG LUONG DINH CUA
A420: CP_TDT | B420: CAO PHONG | C420: CAO PHONG TON DAT TIEN
A421: COOP_CGUOC | B421: COOP MART | C421: COOP CAN GIUOC
A422: COOP_MDUC | B422: COOP MART | C422: COOP MINH DUC
A423: COOP_QLO50 | B423: COOP MART | C423: COOP QUOC LO 50
A424: COOP_LTRUNG | B424: COOP EXTRA | C424: COOP EXTRA LINH TRUNG
A425: COOP_PVD | B425: COOP EXTRA | C425: COOP EXTRA PHAM VAN DONG
A426: COOP_SVH | B426: COOP EXTRA | C426: COOP EXTRA SU VAN HANH
... A591: BIGC_HOME_MYTHO | B591: HOMEMART | C591: HOME MART MY THO
A592: 0 | B592: HOMEMART | C592: HOME MART NGUYEN THI THAP
A593: 0 | B593: HOMEMART | C593: HOME MART NGUYEN VAN DAU
A594: COOP_F_PXUAN | B594: COOP FOOD | C594: COOPFOOD PHU XUAN
A595: VIN_TNINH | B595: VINMART | C595: VINMART TAY NINH
A596: VIN_BRVT | B596: VINMART | C596: VINMART BA RIA VUNG TAU
A597: VIN_BDINH | B597: VINMART | C597: VINMART BINH DINH
A598: VIN_STRANG | B598: VINMART | C598: VINMART SOC TRANG
A599: VIN_BPHUOC | B599: VINMART | C599: VINMART BINH PHUOC
A600: VIN_KTUM | B600: VINMART | C600: VINMART KONTUM
A601: VIN_GLAI | B601: VINMART | C601: VINMART GIA LAI
A602: HD_PICITY | B602: GENSHAI | C602: GENSHAI PICITY
A603: BIGC_HOME_ECO | B603: HOMEMART | C603: HOME MART NGUYEN XIEN
A604: JM_BVD | B604: J MART | C604: J MART
...

Sheet Sheet6
A1: STORE | B1: HỆ THỐNG | C1: MA KH
A2: ACE SU VAN HANH | B2: ACE | C2: ACE_SVH
A3: ACE SONG HANH | B3: ACE | C3: ACE_SH
A4: ACE HOME CELADON | B4: ACE | C4: ACE_CELADON
A5: FOODSMART | B5: FOODSMART | C5: 6442
A6: CTY TNHH THANH NAM THUAN PHAT | B6: KING KONG MART | C6: 6627
A7: BACH HOA BUU DIEN BINH THANH | B7: BACH HOA BUU DIEN | C7: BD_BTHANH
A8: BACH HOA BUU DIEN PHU NHUAN | B8: BACH HOA BUU DIEN | C8: BD_PNHUAN
A9: COOPFOOD WEST | B9: COOP FOOD | C9: COOP_F_WEST
A10: BACH HOA BUU DIEN CU CHI | B10: BACH HOA BUU DIEN | C10: BD_CUCHI
A11: COOPFOOD MIZUKI | B11: COOP FOOD | C11: COOP_F_MIZUKI
A12: COOPFOOD VO NGUYEN GIAP | B12: COOP FOOD | C12: COOP_F_VNGIAP
... A539: HOME MART MY THO | B539: HOMEMART | C539: BIGC_HOME_MYTHO
A540: HOME MART NGUYEN THI THAP | B540: HOMEMART | C540: 0
A541: HOME MART NGUYEN VAN DAU | B541: HOMEMART | C541: 0
A542: HOME MART NGUYEN XIEN | B542: HOMEMART | C542: BIGC_HOME_ECO
A543: J MART | B543: J MART | C543: JM_BVD
A544: K MART AN CAT | B544: K MART | C544: 4932
A545: K MART NGUYET HOA | B545: K MART | C545: 3733
A546: KING FOOD | B546: KING FOOD | C546: 6209
A547: KING FOOD LE VAN SY | B547: KING FOOD | C547: 6209_LVS
A548: KING FOOD TRUONG SON | B548: KING FOOD | C548: 6209_TSON
A549: KING FOOD HUYNH TAN PHAT | B549: KING FOOD | C549: 6209_HTP
A550: KING FOOD PHAM HUNG | B550: KING FOOD | C550: 6209_PH
A551: KOHNAN BINH DUONG | B551: KOHNAN | C551: KOHNAN_BDUONG
A552: KOHNAN BINH TAN | B552: KOHNAN | C552: KOHNAN_BT
A553: KOHNAN HA DONG | B553: KOHNAN | C553: KOHNAN_HDONG
... A639: MEDICARE VINCOM HOA BINH | B639: MEDICARE | C639: ME_CH126
A640: MEDICARE VINCOM HUE | B640: MEDICARE | C640: 0
A641: MEDICARE VINCOM HUNG VUONG | B641: MEDICARE | C641: 0
A642: MEDICARE VINCOM KIEN GIANG | B642: MEDICARE | C642: 0
A643: MEDICARE VINCOM KON TUM | B643: MEDICARE | C643: ME_CH135
A644: MEDICARE VINCOM LANG SON | B644: MEDICARE | C644: ME_CH109
A645: MEDICARE VINCOM LE THANH TON | B645: MEDICARE | C645: 0
A646: MEDICARE VINCOM LE VAN VIET | B646: MEDICARE | C646: ME_CH61
A647: MEDICARE VINCOM LONG XUYEN | B647: MEDICARE | C647: 0
A648: MEDICARE VINCOM LY BON | B648: MEDICARE | C648: 0
A649: MEDICARE VINCOM MONG CAI | B649: MEDICARE | C649: ME_CH125
A650: MEDICARE VINCOM NAM LONG | B650: MEDICARE | C650: ME_CH80
A651: MEDICARE VINCOM NHA TRANG | B651: MEDICARE | C651: ME_CH93
...

Sheet SALE BY STORE
A1: STORE | B1: HỆ THỐNG | C1: MA KH | D1: KA | E1: SUP | F1: SALE | G1: PG | H1: TOTAL TARGET | I1: % | J1: SALE IN | K1: COLEMAN | L1: % | M1: THỰC ĐẠT | N1: FUJITSU | O1: % | P1: THỰC ĐẠT | Q1: BAKING SODA | R1: % | S1: THỰC ĐẠT | T1: AZARINE | U1: % | V1: THỰC ĐẠT
A2: 1 | B2: 2 | C2: 3 | D2: 4 | E2: 5 | F2: 6 | G2: 7 | H2: 8 | I2: 9 | J2: 10 | K2: 11 | L2: 12 | M2: 13 | N2: 14 | O2: 15 | P2: 16 | Q2: 17 | R2: 18 | S2: 19 | T2: 20 | U2: 21 | V2: 22
A3: COOPFOOD PHAM VAN CHIEU | B3: COOP FOOD | C3: =VLOOKUP(A3,CUSTOMER!$A:$C,3,0) -> COOP_F_PVC2 | D3: KA HCM1 | E3: =VLOOKUP(A3,CUSTOMER!$A$2:$H$1094,5,0) -> VAVANCY-VU MINH TUAN | F3: =VLOOKUP(A3,CUSTOMER!$A$2:$I$1094,6,0) -> "NO SALE" | G3: "NO PG" | H3: =SUM(K3,N3,Q3,T3) -> 1244767.1 | I3: =IFERROR(J3/H3,"") -> 0 | J3: =SUM(M3,P3,S3,V3) -> 0 | M3: =SUMIFS(DATA!$L:$L,DATA!$O:$O,$B3,DATA!$N:$N,$A3,DATA!$M:$M,'SALES BY SYSTEM'!$O$1) -> 0 | N3: 0 | O3: =IFERROR(P3/N3,"") | P3: =SUMIFS(DATA!$L:$L,DATA!$O:$O,$B3,DATA!$N:$N,$A3,DATA!$M:$M,'SALES BY SYSTEM'!$O$2) -> 0 | Q3: 1244767.1 | R3: =IFERROR(S3/Q3,"") -> 0 | S3: =SUMIFS(DATA!$L:$L,DATA!$O:$O,$B3,DATA!$N:$N,$A3,DATA!$M:$M,'SALES BY SYSTEM'!$O$4) -> 0 | T3: 0 | U3: =IFERROR(V3/T3,"") | V3: =SUMIFS(DATA!$L:$L,DATA!$O:$O,$B3,DATA!$N:$N,$A3,DATA!$M:$M,'SALES BY SYSTEM'!$O$3) -> 0
A4: COOPFOOD PHONG PHU | B4: COOP FOOD | C4: =VLOOKUP(A4,CUSTOMER!$A:$C,3,0) -> COOP_F_PPHU88 | D4: KA HCM1 | E4: =VLOOKUP(A4,CUSTOMER!$A$2:$H$1094,5,0) -> VAVANCY-VU MINH TUAN | F4: =VLOOKUP(A4,CUSTOMER!$A$2:$I$1094,6,0) -> NO SALE | G4: =VLOOKUP(A4,CUSTOMER!$A$1:$J$1160,7,0) -> "NO PG" | H4: =SUM(K4,N4,Q4,T4) -> 1244767.1 | I4: =IFERROR(J4/H4,"") -> 0 | J4: =SUM(M4,P4,S4,V4) -> 0 | K4: 0 | L4: =IFERROR(M4/K4,"") | M4: =SUMIFS(DATA!$L:$L,DATA!$O:$O,$B4,DATA!$N:$N,$A4,DATA!$M:$M,'SALES BY SYSTEM'!$O$1) -> 0 | N4: 0 | O4: =IFERROR(P4/N4,"") | P4: =SUMIFS(DATA!$L:$L,DATA!$O:$O,$B4,DATA!$N:$N,$A4,DATA!$M:$M,'SALES BY SYSTEM'!$O$2) -> 0 | Q4: 1244767.1 | R4: =IFERROR(S4/Q4,"") -> 0 | S4: =SUMIFS(DATA!$L:$L,DATA!$O:$O,$B4,DATA!$N:$N,$A4,DATA!$M:$M,'SALES BY SYSTEM'!$O$4) -> 0 | T4: 0 | U4: =IFERROR(V4/T4,"") | V4: =SUMIFS(DATA!$L:$L,DATA!$O:$O,$B4,DATA!$N:$N,$A4,DATA!$M:$M,'SALES BY SYSTEM'!$O$3) -> 0
A5: VINMART BINH DUONG | B5: VINMART | C5: =VLOOKUP(A5,CUSTOMER!$A:$C,3,0) -> VIN_BDUONG | D5: KA HCM1 | E5: =VLOOKUP(A5,CUSTOMER!$A$2:$H$1094,5,0) -> TRAN THI THAO NGUYEN | F5: =VLOOKUP(A5,CUSTOMER!$A$2:$I$1094,6,0) -> "NO SALE" | G5: "NO PG" | H5: =SUM(K5,N5,Q5,T5) -> 4.7757909e+08 | I5: =IFERROR(J5/H5,"") -> 0 | J5: =SUM(M5,P5,S5,V5) -> 0 | K5: 0 | L5: =IFERROR(M5/K5,"") | M5: =SUMIFS(DATA!$L:$L,DATA!$O:$O,$B5,DATA!$N:$N,$A5,DATA!$M:$M,'SALES BY SYSTEM'!$O$1) -> 0 | N5: 1.8285541e+08 | O5: =IFERROR(P5/N5,"") -> 0 | P5: =SUMIFS(DATA!$L:$L,DATA!$O:$O,$B5,DATA!$N:$N,$A5,DATA!$M:$M,'SALES BY SYSTEM'!$O$2) -> 0 | Q5: 2.9472368e+08 | R5: =IFERROR(S5/Q5,"") -> 0 | S5: =SUMIFS(DATA!$L:$L,DATA!$O:$O,$B5,DATA!$N:$N,$A5,DATA!$M:$M,'SALES BY SYSTEM'!$O$4) -> 0 | T5: 0 | U5: =IFERROR(V5/T5,"") | V5: =SUMIFS(DATA!$L:$L,DATA!$O:$O,$B5,DATA!$N:$N,$A5,DATA!$M:$M,'SALES BY SYSTEM'!$O$3) -> 0
A6: VINMART+ KHO BINH DUONG | B6: VINMART | C6: =VLOOKUP(A6,CUSTOMER!$A:$C,3,0) -> VIN_KHO_BDUONG+ | D6: KA HCM1 | E6: =VLOOKUP(A6,CUSTOMER!$A$2:$H$1094,5,0) -> #N/A | F6: =VLOOKUP(A6,CUSTOMER!$A$2:$I$1094,6,0) -> #N/A | G6: "NO PG" | H6: =SUM(K6,N6,Q6,T6) -> 1.9325943e+08 | I6: =IFERROR(J6/H6,"") -> 0 | J6: =SUM(M6,P6,S6,V6) -> 0 | K6: 0 | L6: =IFERROR(M6/K6,"") | M6: =SUMIFS(DATA!$L:$L,DATA!$O:$O,$B6,DATA!$N:$N,$A6,DATA!$M:$M,'SALES BY SYSTEM'!$O$1) -> 0 | N6: 73982130 | O6: =IFERROR(P6/N6,"") -> 0 | P6: =SUMIFS(DATA!$L:$L,DATA!$O:$O,$B6,DATA!$N:$N,$A6,DATA!$M:$M,'SALES BY SYSTEM'!$O$2) -> 0 | Q6: 1.192773e+08 | R6: =IFERROR(S6/Q6,"") -> 0 | S6: =SUMIFS(DATA!$L:$L,DATA!$O:$O,$B6,DATA!$N:$N,$A6,DATA!$M:$M,'SALES BY SYSTEM'!$O$4) -> 0 | T6: 0 | U6: =IFERROR(V6/T6,"") | V6: =SUMIFS(DATA!$L:$L,DATA!$O:$O,$B6,DATA!$N:$N,$A6,DATA!$M:$M,'SALES BY SYSTEM'!$O$3) -> 0
A7: VINMART+ ĐÀ NẴNG(1127/171) | B7: VINMART | C7: =VLOOKUP(A7,CUSTOMER!$A:$C,3,0) -> VIN+DNANG | D7: KA HCM1 | E7: =VLOOKUP(A7,CUSTOMER!$A$2:$H$1094,5,0) -> #N/A | F7: =VLOOKUP(A7,CUSTOMER!$A$2:$I$1094,6,0) -> #N/A | G7: "NO PG" | H7: =SUM(K7,N7,Q7,T7) -> 1.4558309e+08 | I7: =IFERROR(J7/H7,"") -> 0 | J7: =SUM(M7,P7,S7,V7) -> 0 | K7: 0 | L7: =IFERROR(M7/K7,"") | M7: =SUMIFS(DATA!$L:$L,DATA!$O:$O,$B7,DATA!$N:$N,$A7,DATA!$M:$M,'SALES BY SYSTEM'!$O$1) -> 0 | N7: 55731032 | O7: =IFERROR(P7/N7,"") -> 0 | P7: =SUMIFS(DATA!$L:$L,DATA!$O:$O,$B7,DATA!$N:$N,$A7,DATA!$M:$M,'SALES BY SYSTEM'!$O$2) -> 0 | Q7: 89852060 | R7: =IFERROR(S7/Q7,"") -> 0 | S7: =SUMIFS(DATA!$L:$L,DATA!$O:$O,$B7,DATA!$N:$N,$A7,DATA!$M:$M,'SALES BY SYSTEM'!$O$4) -> 0 | T7: 0 | U7: =IFERROR(V7/T7,"") | V7: =SUMIFS(DATA!$L:$L,DATA!$O:$O,$B7,DATA!$N:$N,$A7,DATA!$M:$M,'SALES BY SYSTEM'!$O$3) -> 0
A8: LONG CHAU HA NOI | B8: LONG CHAU | C8: =VLOOKUP(A8,CUSTOMER!$A:$C,3,0) -> LC_HN | D8: KA HCM1 | E8: =VLOOKUP(A8,CUSTOMER!$A$2:$H$1094,5,0) -> TRAN THI THAO NGUYEN | F8: =VLOOKUP(A8,CUSTOMER!$A$2:$I$1094,6,0) -> "NO SALE" | G8: "NO PG" | H8: =SUM(K8,N8,Q8,T8) -> 2.5512714e+08 | I8: =IFERROR(J8/H8,"") -> 0 | J8: =SUM(M8,P8,S8,V8) -> 0 | K8: 0 | L8: =IFERROR(M8/K8,"") | M8: =SUMIFS(DATA!$L:$L,DATA!$O:$O,$B8,DATA!$N:$N,$A8,DATA!$M:$M,'SALES BY SYSTEM'!$O$1) -> 0 | N8: 43516721 | O8: =IFERROR(P8/N8,"") -> 0 | P8: =SUMIFS(DATA!$L:$L,DATA!$O:$O,$B8,DATA!$N:$N,$A8,DATA!$M:$M,'SALES BY SYSTEM'!$O$2) -> 0 | Q8: 2.1161041e+08 | R8: =IFERROR(S8/Q8,"") -> 0 | S8: =SUMIFS(DATA!$L:$L,DATA!$O:$O,$B8,DATA!$N:$N,$A8,DATA!$M:$M,'SALES BY SYSTEM'!$O$4) -> 0 | T8: 0 | U8: =IFERROR(V8/T8,"") | V8: =SUMIFS(DATA!$L:$L,DATA!$O:$O,$B8,DATA!$N:$N,$A8,DATA!$M:$M,'SALES BY SYSTEM'!$O$3) -> 0
A9: LONG CHAU HCM | B9: LONG CHAU | C9: =VLOOKUP(A9,CUSTOMER!$A:$C,3,0) -> LC_HCM | D9: KA HCM1 | E9: =VLOOKUP(A9,CUSTOMER!$A$2:$H$1094,5,0) -> TRAN THI THAO NGUYEN | F9: VACANCY | G9: "NO PG" | H9: =SUM(K9,N9,Q9,T9) -> 2.5512714e+08 | I9: =IFERROR(J9/H9,"") -> 0 | J9: =SUM(M9,P9,S9,V9) -> 0 | K9: 0 | L9: =IFERROR(M9/K9,"") | M9: =SUMIFS(DATA!$L:$L,DATA!$O:$O,$B9,DATA!$N:$N,$A9,DATA!$M:$M,'SALES BY SYSTEM'!$O$1) -> 0 | N9: 43516721 | O9: =IFERROR(P9/N9,"") -> 0 | P9: =SUMIFS(DATA!$L:$L,DATA!$O:$O,$B9,DATA!$N:$N,$A9,DATA!$M:$M,'SALES BY SYSTEM'!$O$2) -> 0 | Q9: 2.1161041e+08 | R9: =IFERROR(S9/Q9,"") -> 0 | S9: =SUMIFS(DATA!$L:$L,DATA!$O:$O,$B9,DATA!$N:$N,$A9,DATA!$M:$M,'SALES BY SYSTEM'!$O$4) -> 0 | T9: 0 | U9: =IFERROR(V9/T9,"") | V9: =SUMIFS(DATA!$L:$L,DATA!$O:$O,$B9,DATA!$N:$N,$A9,DATA!$M:$M,'SALES BY SYSTEM'!$O$3) -> 0
A10: CÔNG TY TNHH THISO RETAIL | B10: EMART | C10: =VLOOKUP(A10,CUSTOMER!$A:$C,3,0) -> 4812_THISO | D10: KA HCM1 | E10: =VLOOKUP(A10,CUSTOMER!$A$2:$H$1094,5,0) -> LE NAM PHUONG | F10: =VLOOKUP(A10,CUSTOMER!$A$2:$I$1094,6,0) -> VU THUY MINH THAO | G10: "NO PG" | H10: =SUM(K10,N10,Q10,T10) -> 43516721 | I10: =IFERROR(J10/H10,"") -> 0 | J10: =SUM(M10,P10,S10,V10) -> 0 | K10: 0 | L10: =IFERROR(M10/K10,"") | M10: =SUMIFS(DATA!$L:$L,DATA!$O:$O,$B10,DATA!$N:$N,$A10,DATA!$M:$M,'SALES BY SYSTEM'!$O$1) -> 0 | N10: 43516721 | O10: =IFERROR(P10/N10,"") -> 0 | P10: =SUMIFS(DATA!$L:$L,DATA!$O:$O,$B10,DATA!$N:$N,$A10,DATA!$M:$M,'SALES BY SYSTEM'!$O$2) -> 0 | Q10: 0 | R10: =IFERROR(S10/Q10,"") | S10: =SUMIFS(DATA!$L:$L,DATA!$O:$O,$B10,DATA!$N:$N,$A10,DATA!$M:$M,'SALES BY SYSTEM'!$O$4) -> 0 | T10: 0 | U10: =IFERROR(V10/T10,"") | V10: =SUMIFS(DATA!$L:$L,DATA!$O:$O,$B10,DATA!$N:$N,$A10,DATA!$M:$M,'SALES BY SYSTEM'!$O$3) -> 0
A11: VINMART+ KHO DA NANG | B11: VINMART | C11: =VLOOKUP(A11,CUSTOMER!$A:$C,3,0) -> VIN_KHO_DNANG+ | D11: KA HCM1 | E11: =VLOOKUP(A11,CUSTOMER!$A$2:$H$1094,5,0) -> #N/A | F11: =VLOOKUP(A11,CUSTOMER!$A$2:$I$1094,6,0) -> #N/A | G11: "NO PG" | H11: =SUM(K11,N11,Q11,T11) -> 1.0556903e+08 | I11: =IFERROR(J11/H11,"") -> 0 | J11: =SUM(M11,P11,S11,V11) -> 0 | K11: 0 | L11: =IFERROR(M11/K11,"") | M11: =SUMIFS(DATA!$L:$L,DATA!$O:$O,$B11,DATA!$N:$N,$A11,DATA!$M:$M,'SALES BY SYSTEM'!$O$1) -> 0 | N11: 40413146 | O11: =IFERROR(P11/N11,"") -> 0 | P11: =SUMIFS(DATA!$L:$L,DATA!$O:$O,$B11,DATA!$N:$N,$A11,DATA!$M:$M,'SALES BY SYSTEM'!$O$2) -> 0 | Q11: 65155879 | R11: =IFERROR(S11/Q11,"") -> 0 | S11: =SUMIFS(DATA!$L:$L,DATA!$O:$O,$B11,DATA!$N:$N,$A11,DATA!$M:$M,'SALES BY SYSTEM'!$O$4) -> 0 | T11: 0 | U11: =IFERROR(V11/T11,"") | V11: =SUMIFS(DATA!$L:$L,DATA!$O:$O,$B11,DATA!$N:$N,$A11,DATA!$M:$M,'SALES BY SYSTEM'!$O$3) -> 0
A12: EMART PHAN HUY ICH | B12: EMART | C12: =VLOOKUP(A12,CUSTOMER!$A:$C,3,0) -> 4812_PHI | D12: KA HCM1 | E12: =VLOOKUP(A12,CUSTOMER!$A$2:$H$1094,5,0) -> LE NAM PHUONG | F12: =VLOOKUP(A12,CUSTOMER!$A$2:$I$1094,6,0) -> VU THUY MINH THAO | G12: "NO PG" | H12: =SUM(K12,N12,Q12,T12) -> 21758361 | I12: =IFERROR(J12/H12,"") -> 0 | J12: =SUM(M12,P12,S12,V12) -> 0 | K12: 0 | L12: =IFERROR(M12/K16,"") | M12: =SUMIFS(DATA!$L:$L,DATA!$O:$O,$B12,DATA!$N:$N,$A12,DATA!$M:$M,'SALES BY SYSTEM'!$O$1) -> 0 | N12: 21758361 | O12: =IFERROR(P12/N12,"") -> 0 | P12: =SUMIFS(DATA!$L:$L,DATA!$O:$O,$B12,DATA!$N:$N,$A12,DATA!$M:$M,'SALES BY SYSTEM'!$O$2) -> 0 | Q12: 0 | R12: =IFERROR(S12/Q12,"") | S12: =SUMIFS(DATA!$L:$L,DATA!$O:$O,$B12,DATA!$N:$N,$A12,DATA!$M:$M,'SALES BY SYSTEM'!$O$4) -> 0 | T12: 0 | U12: =IFERROR(V12/T12,"") | V12: =SUMIFS(DATA!$L:$L,DATA!$O:$O,$B12,DATA!$N:$N,$A12,DATA!$M:$M,'SALES BY SYSTEM'!$O$3) -> 0
A13: VINMART+ ĐỒNG NAI(2572/60) | B13: VINMART | C13: =VLOOKUP(A13,CUSTOMER!$A:$C,3,0) -> VIN+DNAI | D13: KA HCM1 | E13: =VLOOKUP(A13,CUSTOMER!$A$2:$H$1094,5,0) -> #N/A | F13: =VLOOKUP(A13,CUSTOMER!$A$2:$I$1094,6,0) -> #N/A | G13: "NO PG" | H13: =SUM(K13,N13,Q13,T13) -> 51081786 | I13: =IFERROR(J13/H13,"") -> 0 | J13: =SUM(M13,P13,S13,V13) -> 0 | K13: 0 | L13: =IFERROR(M13/K13,"") | M13: =SUMIFS(DATA!$L:$L,DATA!$O:$O,$B13,DATA!$N:$N,$A13,DATA!$M:$M,'SALES BY SYSTEM'!$O$1) -> 0 | N13: 19554748 | O13: =IFERROR(P13/N13,"") -> 0 | P13: =SUMIFS(DATA!$L:$L,DATA!$O:$O,$B13,DATA!$N:$N,$A13,DATA!$M:$M,'SALES BY SYSTEM'!$O$2) -> 0 | Q13: 31527038 | R13: =IFERROR(S13/Q13,"") -> 0 | S13: =SUMIFS(DATA!$L:$L,DATA!$O:$O,$B13,DATA!$N:$N,$A13,DATA!$M:$M,'SALES BY SYSTEM'!$O$4) -> 0 | T13: 0 | U13: =IFERROR(V13/T13,"") | V13: =SUMIFS(DATA!$L:$L,DATA!$O:$O,$B13,DATA!$N:$N,$A13,DATA!$M:$M,'SALES BY SYSTEM'!$O$3) -> 0
